Workbook

Sheet Income Statement exp Summary
B2: Income Statement | D2: Year 1 | E2: Year 2 | F2: Year 3 | G2: Year 4 | H2: Year 5 | I2: Year 6 | J2: Year 7 | K2: Year 8 | L2: Year 9 | M2: Year 10 | N2: Year 11 | O2: Year 12 | P2: Year 13 | Q2: Year 14
B3: Number of companies served | C3: Stream 1 | I3: =SUM('Income Statement UAV'!I3,#REF!,#REF!) -> #REF! | J3: =SUM('Income Statement UAV'!J3,#REF!,#REF!) -> #REF! | K3: =SUM('Income Statement UAV'!K3,#REF!,#REF!) -> #REF! | L3: =SUM('Income Statement UAV'!L3,#REF!,#REF!) -> #REF! | M3: =SUM('Income Statement UAV'!M3,#REF!,#REF!) -> #REF! | N3: =SUM('Income Statement UAV'!N3,#REF!,#REF!) -> #REF! | O3: =SUM('Income Statement UAV'!O3,#REF!,#REF!) -> #REF! | P3: =SUM('Income Statement UAV'!P3,#REF!,#REF!) -> #REF! | Q3: =SUM('Income Statement UAV'!Q3,#REF!,#REF!) -> #REF!
B4: service fee/company | S4: service fee/company | T4: How was it verified | U4: We value our service as, if companies are mandated to conduct yearly HSE training courses for their employees; then their option will be to go with either tradition approach sending their employees to local training provider institutes, or hire instructor in house or go with our cost-effective solution: Sending employees to training provider institutes ~ average of 80 employees * 50 OMR per person Total 4000 OMR Inhouse Training Cost of instructor for 3-5 days ~ 1500 OMR: Cost of facility/space renting ~ 500 OMR, cost of materials 300 OMR Total 2,300 OMR VR Training 2,000 OMR
B5: No fo companies | C5: Stream 2 | T5: Our solution will be based on general Safety training procedures for mining site workers and visitors. Some companies want to customize their own other safety training procedures for the we will offer our VR safety training services as per individual companies requirement.
B6: Fee
B7: No of visitors | C7: Stream 3 | S7: Number of visitoers
B8: service fee/company
B9: Revenue | D9: ='Income Statement HSE VR'!D9+'Income Statement Education VR'!D9+'Income Statement UAV'!D9 -> 42900 | E9: ='Income Statement HSE VR'!E9+'Income Statement Education VR'!E9+'Income Statement UAV'!E9 -> 69700 | F9: ='Income Statement HSE VR'!F9+'Income Statement Education VR'!F9+'Income Statement UAV'!F9 -> 112700 | G9: ='Income Statement HSE VR'!G9+'Income Statement Education VR'!G9+'Income Statement UAV'!G9 -> 126800 | H9: ='Income Statement HSE VR'!H9+'Income Statement Education VR'!H9+'Income Statement UAV'!H9 -> 152000 | I9: =SUM('Income Statement UAV'!I9,#REF!,#REF!) -> #REF! | J9: =SUM('Income Statement UAV'!J9,#REF!,#REF!) -> #REF! | K9: =SUM('Income Statement UAV'!K9,#REF!,#REF!) -> #REF! | L9: =SUM('Income Statement UAV'!L9,#REF!,#REF!) -> #REF! | M9: =SUM('Income Statement UAV'!M9,#REF!,#REF!) -> #REF! | N9: =SUM('Income Statement UAV'!N9,#REF!,#REF!) -> #REF! | O9: =SUM('Income Statement UAV'!O9,#REF!,#REF!) -> #REF! | P9: =SUM('Income Statement UAV'!P9,#REF!,#REF!) -> #REF! | Q9: =SUM('Income Statement UAV'!Q9,#REF!,#REF!) -> #REF!
B11: Costs Included in COGS
B12: Number of final devices required | D12: =SUM('Income Statement UAV'!D12,#REF!,#REF!) -> #REF! | E12: =SUM('Income Statement UAV'!E12,#REF!,#REF!) -> #REF! | F12: =SUM('Income Statement UAV'!F12,#REF!,#REF!) -> #REF! | G12: =SUM('Income Statement UAV'!G12,#REF!,#REF!) -> #REF! | H12: =SUM('Income Statement UAV'!H12,#REF!,#REF!) -> #REF! | I12: =SUM('Income Statement UAV'!I12,#REF!,#REF!) -> #REF! | J12: =SUM('Income Statement UAV'!J12,#REF!,#REF!) -> #REF! | K12: =SUM('Income Statement UAV'!K12,#REF!,#REF!) -> #REF! | ... Q12: =SUM('Income Statement UAV'!Q12,#REF!,#REF!) -> #REF!
B13: Devices/Equipment cost | D13: =SUM('Income Statement UAV'!D13,#REF!,#REF!) -> #REF! | E13: =SUM('Income Statement UAV'!E13,#REF!,#REF!) -> #REF! | F13: =SUM('Income Statement UAV'!F13,#REF!,#REF!) -> #REF! | G13: =SUM('Income Statement UAV'!G13,#REF!,#REF!) -> #REF! | H13: =SUM('Income Statement UAV'!H13,#REF!,#REF!) -> #REF! | I13: =SUM('Income Statement UAV'!I13,#REF!,#REF!) -> #REF! | J13: =SUM('Income Statement UAV'!J13,#REF!,#REF!) -> #REF! | K13: =SUM('Income Statement UAV'!K13,#REF!,#REF!) -> #REF! | ... Q13: =SUM('Income Statement UAV'!Q13,#REF!,#REF!) -> #REF!
B14: Development cost | D14: =SUM('Income Statement UAV'!D14,#REF!,#REF!) -> #REF! | E14: =SUM('Income Statement UAV'!E14,#REF!,#REF!) -> #REF! | F14: =SUM('Income Statement UAV'!F14,#REF!,#REF!) -> #REF! | G14: =SUM('Income Statement UAV'!G14,#REF!,#REF!) -> #REF! | H14: =SUM('Income Statement UAV'!H14,#REF!,#REF!) -> #REF! | I14: =SUM('Income Statement UAV'!I14,#REF!,#REF!) -> #REF! | J14: =SUM('Income Statement UAV'!J14,#REF!,#REF!) -> #REF! | K14: =SUM('Income Statement UAV'!K14,#REF!,#REF!) -> #REF! | ... Q14: =SUM('Income Statement UAV'!Q14,#REF!,#REF!) -> #REF!
B15: Customer support | D15: =SUM('Income Statement UAV'!D15,#REF!,#REF!) -> #REF! | E15: =SUM('Income Statement UAV'!E15,#REF!,#REF!) -> #REF! | F15: =SUM('Income Statement UAV'!F15,#REF!,#REF!) -> #REF! | G15: =SUM('Income Statement UAV'!G15,#REF!,#REF!) -> #REF! | H15: =SUM('Income Statement UAV'!H15,#REF!,#REF!) -> #REF! | I15: =SUM('Income Statement UAV'!I15,#REF!,#REF!) -> #REF! | J15: =SUM('Income Statement UAV'!J15,#REF!,#REF!) -> #REF! | K15: =SUM('Income Statement UAV'!K15,#REF!,#REF!) -> #REF! | ... Q15: =SUM('Income Statement UAV'!Q15,#REF!,#REF!) -> #REF!
B16: Internal engineer support | D16: =SUM('Income Statement UAV'!D16,#REF!,#REF!) -> #REF! | E16: =SUM('Income Statement UAV'!E16,#REF!,#REF!) -> #REF! | F16: =SUM('Income Statement UAV'!F16,#REF!,#REF!) -> #REF! | G16: =SUM('Income Statement UAV'!G16,#REF!,#REF!) -> #REF! | H16: =SUM('Income Statement UAV'!H16,#REF!,#REF!) -> #REF! | I16: =SUM('Income Statement UAV'!I16,#REF!,#REF!) -> #REF! | J16: =SUM('Income Statement UAV'!J16,#REF!,#REF!) -> #REF! | K16: =SUM('Income Statement UAV'!K16,#REF!,#REF!) -> #REF! | ... Q16: =SUM('Income Statement UAV'!Q16,#REF!,#REF!) -> #REF!
B17: Other costs | D17: =SUM('Income Statement UAV'!D17,#REF!,#REF!) -> #REF! | E17: =SUM('Income Statement UAV'!E17,#REF!,#REF!) -> #REF! | F17: =SUM('Income Statement UAV'!F17,#REF!,#REF!) -> #REF! | G17: =SUM('Income Statement UAV'!G17,#REF!,#REF!) -> #REF! | H17: =SUM('Income Statement UAV'!H17,#REF!,#REF!) -> #REF! | I17: =SUM('Income Statement UAV'!I17,#REF!,#REF!) -> #REF! | J17: =SUM('Income Statement UAV'!J17,#REF!,#REF!) -> #REF! | K17: =SUM('Income Statement UAV'!K17,#REF!,#REF!) -> #REF! | ... Q17: =SUM('Income Statement UAV'!Q17,#REF!,#REF!) -> #REF!
B18: Supervision | D18: =SUM('Income Statement UAV'!D18,#REF!,#REF!) -> #REF! | E18: =SUM('Income Statement UAV'!E18,#REF!,#REF!) -> #REF! | F18: =SUM('Income Statement UAV'!F18,#REF!,#REF!) -> #REF! | G18: =SUM('Income Statement UAV'!G18,#REF!,#REF!) -> #REF! | H18: =SUM('Income Statement UAV'!H18,#REF!,#REF!) -> #REF! | I18: =SUM('Income Statement UAV'!I18,#REF!,#REF!) -> #REF! | J18: =SUM('Income Statement UAV'!J18,#REF!,#REF!) -> #REF! | K18: =SUM('Income Statement UAV'!K18,#REF!,#REF!) -> #REF! | ... Q18: =SUM('Income Statement UAV'!Q18,#REF!,#REF!) -> #REF!
B19: Total COGS | D19: ='Income Statement HSE VR'!D19+'Income Statement Education VR'!D19+'Income Statement UAV'!D19 -> 5100 | E19: ='Income Statement HSE VR'!E19+'Income Statement Education VR'!E19+'Income Statement UAV'!E19 -> 5100 | F19: ='Income Statement HSE VR'!F19+'Income Statement Education VR'!F19+'Income Statement UAV'!F19 -> 5400 | G19: ='Income Statement HSE VR'!G19+'Income Statement Education VR'!G19+'Income Statement UAV'!G19 -> 5400 | H19: ='Income Statement HSE VR'!H19+'Income Statement Education VR'!H19+'Income Statement UAV'!H19 -> 5700 | I19: =SUM('Income Statement UAV'!I19,#REF!,#REF!) -> #REF! | J19: =SUM('Income Statement UAV'!J19,#REF!,#REF!) -> #REF! | K19: =SUM('Income Statement UAV'!K19,#REF!,#REF!) -> #REF! | L19: =SUM('Income Statement UAV'!L19,#REF!,#REF!) -> #REF! | M19: =SUM('Income Statement UAV'!M19,#REF!,#REF!) -> #REF! | N19: =SUM('Income Statement UAV'!N19,#REF!,#REF!) -> #REF! | O19: =SUM('Income Statement UAV'!O19,#REF!,#REF!) -> #REF! | P19: =SUM('Income Statement UAV'!P19,#REF!,#REF!) -> #REF! | Q19: =SUM('Income Statement UAV'!Q19,#REF!,#REF!) -> #REF!
B21: Gross Profit | D21: ='Income Statement HSE VR'!D21+'Income Statement Education VR'!D21+'Income Statement UAV'!D21 -> 37800 | E21: ='Income Statement HSE VR'!E21+'Income Statement Education VR'!E21+'Income Statement UAV'!E21 -> 64600 | F21: ='Income Statement HSE VR'!F21+'Income Statement Education VR'!F21+'Income Statement UAV'!F21 -> 107300 | G21: ='Income Statement HSE VR'!G21+'Income Statement Education VR'!G21+'Income Statement UAV'!G21 -> 121400 | H21: ='Income Statement HSE VR'!H21+'Income Statement Education VR'!H21+'Income Statement UAV'!H21 -> 146300 | I21: =SUM('Income Statement UAV'!I21,#REF!,#REF!) -> #REF! | J21: =SUM('Income Statement UAV'!J21,#REF!,#REF!) -> #REF! | K21: =SUM('Income Statement UAV'!K21,#REF!,#REF!) -> #REF! | L21: =SUM('Income Statement UAV'!L21,#REF!,#REF!) -> #REF! | M21: =SUM('Income Statement UAV'!M21,#REF!,#REF!) -> #REF! | N21: =SUM('Income Statement UAV'!N21,#REF!,#REF!) -> #REF! | O21: =SUM('Income Statement UAV'!O21,#REF!,#REF!) -> #REF! | P21: =SUM('Income Statement UAV'!P21,#REF!,#REF!) -> #REF! | Q21: =SUM('Income Statement UAV'!Q21,#REF!,#REF!) -> #REF!
B23: Production Overhead
B24: Rent of Production Premises | D24: =SUM('Income Statement UAV'!D24,#REF!,#REF!) -> #REF! | E24: =SUM('Income Statement UAV'!E24,#REF!,#REF!) -> #REF! | F24: =SUM('Income Statement UAV'!F24,#REF!,#REF!) -> #REF! | G24: =SUM('Income Statement UAV'!G24,#REF!,#REF!) -> #REF! | H24: =SUM('Income Statement UAV'!H24,#REF!,#REF!) -> #REF! | I24: =SUM('Income Statement UAV'!I24,#REF!,#REF!) -> #REF! | J24: =SUM('Income Statement UAV'!J24,#REF!,#REF!) -> #REF! | K24: =SUM('Income Statement UAV'!K24,#REF!,#REF!) -> #REF! | ... Q24: =SUM('Income Statement UAV'!Q24,#REF!,#REF!) -> #REF!
B25: Non-Production Electricity | D25: =SUM('Income Statement UAV'!D25,#REF!,#REF!) -> #REF! | E25: =SUM('Income Statement UAV'!E25,#REF!,#REF!) -> #REF! | F25: =SUM('Income Statement UAV'!F25,#REF!,#REF!) -> #REF! | G25: =SUM('Income Statement UAV'!G25,#REF!,#REF!) -> #REF! | H25: =SUM('Income Statement UAV'!H25,#REF!,#REF!) -> #REF! | I25: =SUM('Income Statement UAV'!I25,#REF!,#REF!) -> #REF! | J25: =SUM('Income Statement UAV'!J25,#REF!,#REF!) -> #REF! | K25: =SUM('Income Statement UAV'!K25,#REF!,#REF!) -> #REF! | ... Q25: =SUM('Income Statement UAV'!Q25,#REF!,#REF!) -> #REF!
B26: Staff Costs | D26: =SUM('Income Statement UAV'!D26,#REF!,#REF!) -> #REF! | E26: =SUM('Income Statement UAV'!E26,#REF!,#REF!) -> #REF! | F26: =SUM('Income Statement UAV'!F26,#REF!,#REF!) -> #REF! | G26: =SUM('Income Statement UAV'!G26,#REF!,#REF!) -> #REF! | H26: =SUM('Income Statement UAV'!H26,#REF!,#REF!) -> #REF! | I26: =SUM('Income Statement UAV'!I26,#REF!,#REF!) -> #REF! | J26: =SUM('Income Statement UAV'!J26,#REF!,#REF!) -> #REF! | K26: =SUM('Income Statement UAV'!K26,#REF!,#REF!) -> #REF! | ... Q26: =SUM('Income Statement UAV'!Q26,#REF!,#REF!) -> #REF!
B27: Production Maintenance | D27: =SUM('Income Statement UAV'!D27,#REF!,#REF!) -> #REF! | E27: =SUM('Income Statement UAV'!E27,#REF!,#REF!) -> #REF! | F27: =SUM('Income Statement UAV'!F27,#REF!,#REF!) -> #REF! | G27: =SUM('Income Statement UAV'!G27,#REF!,#REF!) -> #REF! | H27: =SUM('Income Statement UAV'!H27,#REF!,#REF!) -> #REF! | I27: =SUM('Income Statement UAV'!I27,#REF!,#REF!) -> #REF! | J27: =SUM('Income Statement UAV'!J27,#REF!,#REF!) -> #REF! | K27: =SUM('Income Statement UAV'!K27,#REF!,#REF!) -> #REF! | ... Q27: =SUM('Income Statement UAV'!Q27,#REF!,#REF!) -> #REF!
B28: Carriage Inwards not in COGS | D28: =SUM('Income Statement UAV'!D28,#REF!,#REF!) -> #REF! | E28: =SUM('Income Statement UAV'!E28,#REF!,#REF!) -> #REF! | F28: =SUM('Income Statement UAV'!F28,#REF!,#REF!) -> #REF! | G28: =SUM('Income Statement UAV'!G28,#REF!,#REF!) -> #REF! | H28: =SUM('Income Statement UAV'!H28,#REF!,#REF!) -> #REF! | I28: =SUM('Income Statement UAV'!I28,#REF!,#REF!) -> #REF! | J28: =SUM('Income Statement UAV'!J28,#REF!,#REF!) -> #REF! | K28: =SUM('Income Statement UAV'!K28,#REF!,#REF!) -> #REF! | ... Q28: =SUM('Income Statement UAV'!Q28,#REF!,#REF!) -> #REF!
B29: Labour (not used in Production) | D29: =SUM('Income Statement UAV'!D29,#REF!,#REF!) -> #REF! | E29: =SUM('Income Statement UAV'!E29,#REF!,#REF!) -> #REF! | F29: =SUM('Income Statement UAV'!F29,#REF!,#REF!) -> #REF! | G29: =SUM('Income Statement UAV'!G29,#REF!,#REF!) -> #REF! | H29: =SUM('Income Statement UAV'!H29,#REF!,#REF!) -> #REF! | I29: =SUM('Income Statement UAV'!I29,#REF!,#REF!) -> #REF! | J29: =SUM('Income Statement UAV'!J29,#REF!,#REF!) -> #REF! | K29: =SUM('Income Statement UAV'!K29,#REF!,#REF!) -> #REF! | ... Q29: =SUM('Income Statement UAV'!Q29,#REF!,#REF!) -> #REF!
B30: Total Production Overhead | D30: ='Income Statement HSE VR'!D30+'Income Statement Education VR'!D30+'Income Statement UAV'!D30 -> 0 | E30: ='Income Statement HSE VR'!E30+'Income Statement Education VR'!E30+'Income Statement UAV'!E30 -> 0 | F30: ='Income Statement HSE VR'!F30+'Income Statement Education VR'!F30+'Income Statement UAV'!F30 -> 0 | G30: ='Income Statement HSE VR'!G30+'Income Statement Education VR'!G30+'Income Statement UAV'!G30 -> 0 | H30: ='Income Statement HSE VR'!H30+'Income Statement Education VR'!H30+'Income Statement UAV'!H30 -> 0 | I30: =SUM('Income Statement UAV'!I30,#REF!,#REF!) -> #REF! | J30: =SUM('Income Statement UAV'!J30,#REF!,#REF!) -> #REF! | K30: =SUM('Income Statement UAV'!K30,#REF!,#REF!) -> #REF! | L30: =SUM('Income Statement UAV'!L30,#REF!,#REF!) -> #REF! | M30: =SUM('Income Statement UAV'!M30,#REF!,#REF!) -> #REF! | N30: =SUM('Income Statement UAV'!N30,#REF!,#REF!) -> #REF! | O30: =SUM('Income Statement UAV'!O30,#REF!,#REF!) -> #REF! | P30: =SUM('Income Statement UAV'!P30,#REF!,#REF!) -> #REF! | Q30: =SUM('Income Statement UAV'!Q30,#REF!,#REF!) -> #REF!
B32: Selling and Admin Overhead Costs
B33: Rent (Office only) | D33: =SUM('Income Statement UAV'!D33,#REF!,#REF!) -> #REF! | E33: =SUM('Income Statement UAV'!E33,#REF!,#REF!) -> #REF! | F33: =SUM('Income Statement UAV'!F33,#REF!,#REF!) -> #REF! | G33: =SUM('Income Statement UAV'!G33,#REF!,#REF!) -> #REF! | H33: =SUM('Income Statement UAV'!H33,#REF!,#REF!) -> #REF! | I33: =SUM('Income Statement UAV'!I33,#REF!,#REF!) -> #REF! | J33: =SUM('Income Statement UAV'!J33,#REF!,#REF!) -> #REF! | K33: =SUM('Income Statement UAV'!K33,#REF!,#REF!) -> #REF! | ... Q33: =SUM('Income Statement UAV'!Q33,#REF!,#REF!) -> #REF!
B34: Warehouse rent | D34: =SUM('Income Statement UAV'!D34,#REF!,#REF!) -> #REF! | E34: =SUM('Income Statement UAV'!E34,#REF!,#REF!) -> #REF! | F34: =SUM('Income Statement UAV'!F34,#REF!,#REF!) -> #REF! | G34: =SUM('Income Statement UAV'!G34,#REF!,#REF!) -> #REF! | H34: =SUM('Income Statement UAV'!H34,#REF!,#REF!) -> #REF! | I34: =SUM('Income Statement UAV'!I34,#REF!,#REF!) -> #REF! | J34: =SUM('Income Statement UAV'!J34,#REF!,#REF!) -> #REF! | K34: =SUM('Income Statement UAV'!K34,#REF!,#REF!) -> #REF! | ... Q34: =SUM('Income Statement UAV'!Q34,#REF!,#REF!) -> #REF!
B35: Logistics cost | D35: =SUM('Income Statement UAV'!D35,#REF!,#REF!) -> #REF! | E35: =SUM('Income Statement UAV'!E35,#REF!,#REF!) -> #REF! | F35: =SUM('Income Statement UAV'!F35,#REF!,#REF!) -> #REF! | G35: =SUM('Income Statement UAV'!G35,#REF!,#REF!) -> #REF! | H35: =SUM('Income Statement UAV'!H35,#REF!,#REF!) -> #REF! | I35: =SUM('Income Statement UAV'!I35,#REF!,#REF!) -> #REF! | J35: =SUM('Income Statement UAV'!J35,#REF!,#REF!) -> #REF! | K35: =SUM('Income Statement UAV'!K35,#REF!,#REF!) -> #REF! | ... Q35: =SUM('Income Statement UAV'!Q35,#REF!,#REF!) -> #REF!
B36: Management Salary | D36: =SUM('Income Statement UAV'!D36,#REF!,#REF!) -> #REF! | E36: =SUM('Income Statement UAV'!E36,#REF!,#REF!) -> #REF! | F36: =SUM('Income Statement UAV'!F36,#REF!,#REF!) -> #REF! | G36: =SUM('Income Statement UAV'!G36,#REF!,#REF!) -> #REF! | H36: =SUM('Income Statement UAV'!H36,#REF!,#REF!) -> #REF! | I36: =SUM('Income Statement UAV'!I36,#REF!,#REF!) -> #REF! | J36: =SUM('Income Statement UAV'!J36,#REF!,#REF!) -> #REF! | K36: =SUM('Income Statement UAV'!K36,#REF!,#REF!) -> #REF! | ... Q36: =SUM('Income Statement UAV'!Q36,#REF!,#REF!) -> #REF!
B37: Staff Salary | D37: =SUM('Income Statement UAV'!D37,#REF!,#REF!) -> #REF! | E37: =SUM('Income Statement UAV'!E37,#REF!,#REF!) -> #REF! | F37: =SUM('Income Statement UAV'!F37,#REF!,#REF!) -> #REF! | G37: =SUM('Income Statement UAV'!G37,#REF!,#REF!) -> #REF! | H37: =SUM('Income Statement UAV'!H37,#REF!,#REF!) -> #REF! | I37: =SUM('Income Statement UAV'!I37,#REF!,#REF!) -> #REF! | J37: =SUM('Income Statement UAV'!J37,#REF!,#REF!) -> #REF! | K37: =SUM('Income Statement UAV'!K37,#REF!,#REF!) -> #REF! | ... Q37: =SUM('Income Statement UAV'!Q37,#REF!,#REF!) -> #REF!
B38: Labour Cost (ancillary) | D38: =SUM('Income Statement UAV'!D38,#REF!,#REF!) -> #REF! | E38: =SUM('Income Statement UAV'!E38,#REF!,#REF!) -> #REF! | F38: =SUM('Income Statement UAV'!F38,#REF!,#REF!) -> #REF! | G38: =SUM('Income Statement UAV'!G38,#REF!,#REF!) -> #REF! | H38: =SUM('Income Statement UAV'!H38,#REF!,#REF!) -> #REF! | I38: =SUM('Income Statement UAV'!I38,#REF!,#REF!) -> #REF! | J38: =SUM('Income Statement UAV'!J38,#REF!,#REF!) -> #REF! | K38: =SUM('Income Statement UAV'!K38,#REF!,#REF!) -> #REF! | ... Q38: =SUM('Income Statement UAV'!Q38,#REF!,#REF!) -> #REF!
B39: Electricity Cost | D39: =SUM('Income Statement UAV'!D39,#REF!,#REF!) -> #REF! | E39: =SUM('Income Statement UAV'!E39,#REF!,#REF!) -> #REF! | F39: =SUM('Income Statement UAV'!F39,#REF!,#REF!) -> #REF! | G39: =SUM('Income Statement UAV'!G39,#REF!,#REF!) -> #REF! | H39: =SUM('Income Statement UAV'!H39,#REF!,#REF!) -> #REF! | I39: =SUM('Income Statement UAV'!I39,#REF!,#REF!) -> #REF! | J39: =SUM('Income Statement UAV'!J39,#REF!,#REF!) -> #REF! | K39: =SUM('Income Statement UAV'!K39,#REF!,#REF!) -> #REF! | ... Q39: =SUM('Income Statement UAV'!Q39,#REF!,#REF!) -> #REF!
B40: Administration costs | D40: =SUM('Income Statement UAV'!D40,#REF!,#REF!) -> #REF! | E40: =SUM('Income Statement UAV'!E40,#REF!,#REF!) -> #REF! | F40: =SUM('Income Statement UAV'!F40,#REF!,#REF!) -> #REF! | G40: =SUM('Income Statement UAV'!G40,#REF!,#REF!) -> #REF! | H40: =SUM('Income Statement UAV'!H40,#REF!,#REF!) -> #REF! | I40: =SUM('Income Statement UAV'!I40,#REF!,#REF!) -> #REF! | J40: =SUM('Income Statement UAV'!J40,#REF!,#REF!) -> #REF! | K40: =SUM('Income Statement UAV'!K40,#REF!,#REF!) -> #REF! | ... Q40: =SUM('Income Statement UAV'!Q40,#REF!,#REF!) -> #REF!
B41: Water Cost | D41: =SUM('Income Statement UAV'!D41,#REF!,#REF!) -> #REF! | E41: =SUM('Income Statement UAV'!E41,#REF!,#REF!) -> #REF! | F41: =SUM('Income Statement UAV'!F41,#REF!,#REF!) -> #REF! | G41: =SUM('Income Statement UAV'!G41,#REF!,#REF!) -> #REF! | H41: =SUM('Income Statement UAV'!H41,#REF!,#REF!) -> #REF! | I41: =SUM('Income Statement UAV'!I41,#REF!,#REF!) -> #REF! | J41: =SUM('Income Statement UAV'!J41,#REF!,#REF!) -> #REF! | K41: =SUM('Income Statement UAV'!K41,#REF!,#REF!) -> #REF! | ... Q41: =SUM('Income Statement UAV'!Q41,#REF!,#REF!) -> #REF!
B42: Fuel Cost | D42: =SUM('Income Statement UAV'!D42,#REF!,#REF!) -> #REF! | E42: =SUM('Income Statement UAV'!E42,#REF!,#REF!) -> #REF! | F42: =SUM('Income Statement UAV'!F42,#REF!,#REF!) -> #REF! | G42: =SUM('Income Statement UAV'!G42,#REF!,#REF!) -> #REF! | H42: =SUM('Income Statement UAV'!H42,#REF!,#REF!) -> #REF! | I42: =SUM('Income Statement UAV'!I42,#REF!,#REF!) -> #REF! | J42: =SUM('Income Statement UAV'!J42,#REF!,#REF!) -> #REF! | K42: =SUM('Income Statement UAV'!K42,#REF!,#REF!) -> #REF! | ... Q42: =SUM('Income Statement UAV'!Q42,#REF!,#REF!) -> #REF!
B43: Telephone | D43: =SUM('Income Statement UAV'!D43,#REF!,#REF!) -> #REF! | E43: =SUM('Income Statement UAV'!E43,#REF!,#REF!) -> #REF! | F43: =SUM('Income Statement UAV'!F43,#REF!,#REF!) -> #REF! | G43: =SUM('Income Statement UAV'!G43,#REF!,#REF!) -> #REF! | H43: =SUM('Income Statement UAV'!H43,#REF!,#REF!) -> #REF! | I43: =SUM('Income Statement UAV'!I43,#REF!,#REF!) -> #REF! | J43: =SUM('Income Statement UAV'!J43,#REF!,#REF!) -> #REF! | K43: =SUM('Income Statement UAV'!K43,#REF!,#REF!) -> #REF! | ... Q43: =SUM('Income Statement UAV'!Q43,#REF!,#REF!) -> #REF!
B44: Internet | D44: =SUM('Income Statement UAV'!D44,#REF!,#REF!) -> #REF! | E44: =SUM('Income Statement UAV'!E44,#REF!,#REF!) -> #REF! | F44: =SUM('Income Statement UAV'!F44,#REF!,#REF!) -> #REF! | G44: =SUM('Income Statement UAV'!G44,#REF!,#REF!) -> #REF! | H44: =SUM('Income Statement UAV'!H44,#REF!,#REF!) -> #REF! | I44: =SUM('Income Statement UAV'!I44,#REF!,#REF!) -> #REF! | J44: =SUM('Income Statement UAV'!J44,#REF!,#REF!) -> #REF! | K44: =SUM('Income Statement UAV'!K44,#REF!,#REF!) -> #REF! | ... Q44: =SUM('Income Statement UAV'!Q44,#REF!,#REF!) -> #REF!
... B54: Start-up Expenses (Compliance, Marketing, Overheads) | D54: =SUM('Income Statement UAV'!D54,#REF!,#REF!) -> #REF! | E54: =SUM('Income Statement UAV'!E54,#REF!,#REF!) -> #REF! | F54: =SUM('Income Statement UAV'!F54,#REF!,#REF!) -> #REF! | G54: =SUM('Income Statement UAV'!G54,#REF!,#REF!) -> #REF! | H54: =SUM('Income Statement UAV'!H54,#REF!,#REF!) -> #REF! | I54: =SUM('Income Statement UAV'!I54,#REF!,#REF!) -> #REF! | J54: =SUM('Income Statement UAV'!J54,#REF!,#REF!) -> #REF! | K54: =SUM('Income Statement UAV'!K54,#REF!,#REF!) -> #REF! | ... Q54: =SUM('Income Statement UAV'!Q54,#REF!,#REF!) -> #REF!
...

Sheet Sheet2
B2: Income Statement | D2: Year 1 | E2: Year 2 | F2: Year 3 | G2: Year 4 | H2: Year 5 | J2: Cashflow | K2: Year 1 | L2: Year 2 | M2: Year 3 | N2: Year 4 | O2: Year 5
B3: Revenue | D3: 42900 | E3: 69700 | F3: 112700 | G3: 126800 | H3: 152000 | J3: Cashflow from operation
J4: Net income (income statement) | K4: 4064.3333 | L4: 39155.667 | M4: 74011 | N4: 86782.667 | O4: 110935.67
B5: Total COGS | D5: 5100 | E5: 5100 | F5: 5400 | G5: 5400 | H5: 5700 | J5: Additions to cashflow | K5: 3166.6667 | L5: 4333.3333 | M5: 5500 | N5: 4333.3333 | O5: 4333.3333
J6: Depreciation | K6: 3166.6667 | L6: 4333.3333 | M6: 5500 | N6: 4333.3333 | O6: 4333.3333
B7: Gross Profit | D7: 37800 | E7: 64600 | F7: 107300 | G7: 121400 | H7: 146300 | J7: Increase in accounts payable
J8: Subtraction from cashflow | K8: 0 | L8: 0 | M8: 0 | N8: 0 | O8: 0
B9: Total Selling and Admin Overhead Costs | D9: 30400 | E9: 19900 | F9: 25500 | G9: 27600 | H9: 27600 | J9: Increase in accounts receivable
B10: Total Overhead Costs | D10: 30400 | E10: 19900 | F10: 25500 | G10: 27600 | H10: 27600 | J10: Increase in inventory
J11: Net cash from operations | K11: 7231 | L11: 43489 | M11: 79511 | N11: 91116 | O11: 115269
B12: EBITDA | D12: 7400 | E12: 44700 | F12: 81800 | G12: 93800 | H12: 118700 | J12: Cash flow from investing | K12: 9500 | L12: 3500 | M12: 3500 | N12: 6000 | O12: 3500
B13: EBITDA % | D13: 0.17249417 | E13: 0.64131994 | F13: 0.72582076 | G13: 0.73974763 | H13: 0.78092105 | J13: Purchase of equipment | K13: 9500 | L13: 3500 | M13: 3500 | N13: 6000 | O13: 3500
J14: Cash flow from financing | K14: 0 | L14: 0 | M14: 0 | N14: 0 | O14: 0
B15: Depreciation | D15: 3166.6667 | E15: 4333.3333 | F15: 5500 | G15: 4333.3333 | H15: 4333.3333 | J15: Notes payable(loan from bank)
J16: Net Cashflow | K16: -2269 | L16: 39989 | M16: 76011 | N16: 85116 | O16: 111769
B17: EBT | D17: 4233.3333 | E17: 40366.667 | F17: 76300 | G17: 89466.667 | H17: 114366.67
B18: EBT % | D18: 0.098679099 | E18: 0.57914873 | F18: 0.67701863 | G18: 0.70557308 | H18: 0.75241228 | J18: Total Revenue | K18: 42900 | L18: 69700 | M18: 112700 | N18: 126800 | O18: 152000
B19: Tax @ 15% | D19: 169 | E19: 1211 | F19: 2289 | G19: 2684 | H19: 3431 | J19: Total cost requiredIncluding equipment cost | K19: 45000 | L19: 28500 | M19: 34400 | N19: 39000 | O19: 36800
B20: Net Profit/Income | D20: 4064.3333 | E20: 39155.667 | F20: 74011 | G20: 86782.667 | H20: 110935.67 | J20: Net Cashflow | K20: -2269 | L20: 39989 | M20: 76011 | N20: 85116 | O20: 111769
B21: Net Profit % | D21: 0.094739705 | E21: 0.56177427 | F21: 0.65670807 | G21: 0.68440589 | H21: 0.72983991
J22: Total Equipment cost | K22: 9500 | L22: 3500 | M22: 3500 | N22: 6000 | O22: 3500

Sheet Income Statement HSE VR
B2: Income Statement | D2: Year 1 | E2: Year 2 | F2: Year 3 | G2: Year 4 | H2: Year 5 | I2: Year 6 | J2: Year 7 | K2: Year 8 | L2: Year 9 | M2: Year 10 | N2: Year 11 | O2: Year 12 | P2: Year 13 | Q2: Year 14 | S2: Assumption | T2: Verfication of assumption | U2: Remarks if any
B3: Number of companies served | C3: Stream 1 Training HSE | D3: 5 | E3: 10 | F3: 12 | G3: 14 | H3: 16 | I3: 12 | J3: 12 | K3: 12 | L3: 12 | M3: 12 | N3: 12 | O3: 12 | P3: 12 | Q3: 12 | S3: Number of companies served | T3: How was it verified | U3: Since we estimated 20 number of major companies operating in mining in Oman, for first year we estimated 25% companies will avail our service, next year 50%
B4: service fee/company | D4: 2000 | E4: 2000 | F4: 2000 | G4: 2000 | H4: 2000 | S4: service fee/company | T4: How was it verified | U4: We value our service as, if companies are mandated to conduct yearly HSE training courses for their employees; then their option will be to go with either tradition approach sending their employees to local training provider institutes, or hire instructor in house or go with our cost-effective solution: Sending employees to training provider institutes ~ average of 80 employees * 50 OMR per person Total 4000 OMR Inhouse Training Cost of instructor for 3-5 days ~ 1500 OMR: Cost of facility/space renting ~ 500 OMR, cost of materials 300 OMR Total 2,300 OMR VR Training 2,000 OMR
B5: No fo companies | C5: Stream 2 Customization Services | D5: 1 | E5: 2 | F5: 3 | G5: 3 | H5: 3 | T5: Our solution will be based on general Safety training procedures for mining site workers and visitors. Some companies want to customize their own other safety training procedures for the we will offer our VR safety training services as per individual companies requirement.
B6: Fee | D6: 900 | E6: 900 | F6: 1000 | G6: 1000 | H6: 1000
B7: No of visitors | C7: Stream 3 Visitors | D7: 400 | E7: 500 | F7: 600 | G7: 600 | H7: 600 | S7: Number of visitoers | T7: Since we are presenting this solution inside the mining 4IR center; and visitors are expected to visit the center for all developed application and presented technology. So, we have estimated yearly number of visitors for the center and divided for now by 3 applications income. Example first year estimated number of visitors 1200, each application can contribute of 400 visitors per year
B8: Service fee | D8: 3 | E8: 3 | F8: 4 | G8: 4 | H8: 4
B9: TotalRevenue | D9: =D3*D4+D5*D6+D7*D8 -> 12100 | E9: =E3*E4+E5*E6+E7*E8 -> 23300 | F9: =F3*F4+F5*F6+F7*F8 -> 29400 | G9: =G3*G4+G5*G6+G7*G8 -> 33400 | H9: =H3*H4+H5*H6+H7*H8 -> 37400 | I9: =I3*I4+I5*I6+I7*I8 -> 0 | J9: =J3*J4+J5*J6+J7*J8 -> 0 | K9: =K3*K4+K5*K6+K7*K8 -> 0 | ... Q9: =Q3*Q4+Q5*Q6+Q7*Q8 -> 0
B11: Costs Included in COGS | S11: Costs Included in COGS | T11: Reason and logic for assumption | U11: Remarks if any
B12: Number of final devices required | D12: 20 | E12: 20 | F12: 20 | G12: 20 | H12: 20 | I12: 15 | J12: 15 | K12: 15 | L12: 15 | M12: 15 | N12: 15 | O12: 15 | P12: 15 | Q12: 15 | S12: Number of final devices required | T12: Reason and logic | U12: Total of 20 VR (15 for training, 5 for visitors) headset to be purchase for first Year and increase and replace for following years
B15: Customer support | D15: 500 | E15: 500 | F15: 600 | G15: 600 | H15: 700 | S15: Customer support | T15: Reason and logic | U15: Estimated based on customers support calls
B16: Internal engineer support | D16: 100 | E16: 100 | F16: 100 | G16: 100 | H16: 100 | S16: Internal engineer support | T16: Reason and logic
B17: Other costs | D17: 1000 | E17: 1000 | F17: 1000 | G17: 1000 | H17: 1000 | S17: Other costs | T17: Reason and logic | U17: Backup cost/ Contingency every year 1,000 OMR for
B18: Supervision | D18: 100 | E18: 100 | F18: 100 | G18: 100 | H18: 100 | S18: Supervision | T18: Reason and logic
B19: Total COGS | D19: =SUM(D13:D18) -> 1700 | E19: =SUM(E13:E18) -> 1700 | F19: =SUM(F13:F18) -> 1800 | G19: =SUM(G13:G18) -> 1800 | H19: =SUM(H13:H18) -> 1900 | I19: =SUM(I13:I18) -> 0 | J19: =SUM(J13:J18) -> 0 | K19: =SUM(K13:K18) -> 0 | ... Q19: =SUM(Q13:Q18) -> 0
B21: Gross Profit | D21: =D9-D19 -> 10400 | E21: =E9-E19 -> 21600 | F21: =F9-F19 -> 27600 | G21: =G9-G19 -> 31600 | H21: =H9-H19 -> 35500 | I21: =I9-I19 -> 0 | J21: =J9-J19 -> 0 | K21: =K9-K19 -> 0 | ... Q21: =Q9-Q19 -> 0
B23: Production Overhead | S23: Production Overhead | T23: Reason and logic for assumption | U23: Remarks if any
B24: Rent of Production Premises | S24: Rent of Production Premises | T24: Reason and logic
B25: Non-Production Electricity | S25: Non-Production Electricity | T25: Reason and logic
B26: Staff Costs | S26: Staff Costs | T26: Reason and logic
B27: Production Maintenance | S27: Production Maintenance | T27: Reason and logic
B28: Carriage Inwards not in COGS | S28: Carriage Inwards not in COGS | T28: Reason and logic
B29: Labour (not used in Production) | S29: Labour (not used in Production) | T29: Reason and logic
B30: Total Production Overhead | D30: =SUM(D24:D29) -> 0 | E30: =SUM(E24:E29) -> 0 | F30: =SUM(F24:F29) -> 0 | G30: =SUM(G24:G29) -> 0 | H30: =SUM(H24:H29) -> 0 | I30: =SUM(I24:I29) -> 0 | J30: =SUM(J24:J29) -> 0 | K30: =SUM(K24:K29) -> 0 | ... Q30: =SUM(Q24:Q29) -> 0
B32: Selling and Admin Overhead Costs | S32: Selling and Admin Overhead Costs | T32: Reason and logic for assumption | U32: Remarks if any
B33: Rent | D33: 3600 | E33: 3600 | F33: 4800 | G33: 6000 | H33: 6000 | S33: Rent (Office only) | T33: Reason and logic | U33: Since the center facility will be used by all applications; then the yearly renting cost will be divided by 3. Example for first year the renting fees per month 900 OMR each application will contributes of 300 OMR per month for the rent. Per year 3600 OMR
B34: Warehouse rent | S34: Warehouse rent | T34: Reason and logic
B35: Logistics cost | S35: Logistics cost | T35: Reason and logic
B36: Management Salary | S36: Management Salary | T36: Reason and logic
B37: Staff Salary | S37: Staff Salary | T37: Reason and logic
B38: Labour Cost (ancillary) | S38: Labour Cost (ancillary) | T38: Reason and logic
B39: Electricity Cost | S39: Electricity Cost | T39: Reason and logic
B40: Administration costs | S40: Administration costs | T40: Reason and logic
B41: Water Cost | S41: Water Cost | T41: Reason and logic
B42: Fuel Cost | S42: Fuel Cost | T42: Reason and logic
B43: Telephone | S43: Telephone | T43: Reason and logic
B44: Internet | S44: Internet | T44: Reason and logic
B45: Travel / Flights | S45: Travel / Flights | T45: Reason and logic
... B50: Startup Costs | S50: Startup Costs | T50: Reason and logic
B51: Product development | D51: 6000 | E51: 2000 | F51: 2500 | G51: 2000 | H51: 2000 | S51: Product development | T51: Reason and logic | U51: Development cost ~ 6000 OMR first year and every following years to modify/add new functions
...

Sheet Income Statement Education VR
B2: Income Statement | D2: Year 1 | E2: Year 2 | F2: Year 3 | G2: Year 4 | H2: Year 5 | I2: Year 6 | J2: Year 7 | K2: Year 8 | L2: Year 9 | M2: Year 10 | N2: Year 11 | O2: Year 12 | P2: Year 13 | Q2: Year 14 | S2: Assumption | T2: Verfication of assumption | U2: Remarks if any
B3: Number of Private Schools served | C3: Stream 1 VR Toolkit Fees | D3: 6 | E3: 9 | F3: 15 | G3: 16 | H3: 20 | I3: 12 | J3: 12 | K3: 12 | L3: 12 | M3: 12 | N3: 12 | O3: 12 | P3: 12 | Q3: 12 | S3: Number of Private Schools served | T3: How was it verified | U3: As per recorders there are over 500 private schools in Oman, out of them we estimate at least 30 top elite schools we are targeting for this product as early adapters. for first year we estimated 20% of them will purchase our products for first year. 30% year two, 50% year3,
B4: service fee/company | D4: 2000 | E4: 2200 | F4: 2500 | G4: 2700 | H4: 2700 | I4: 2000 | J4: 2000 | K4: 2000 | L4: 2000 | M4: 2000 | N4: 2000 | O4: 2000 | P4: 2000 | Q4: 2000 | S4: VR Toolkit Fees | T4: How was it verified | U4: Since there is no comparable product currently used by schools, we will use the cost plus to estimate our service. 6000 total development cost for first year in which will need to retain the cost from 50% from our estimated schools will buy our products in first year. So, 6000/3 = 2000 OMR
B5: No fo Private Schools | C5: Stream 2 Customization Services | D5: 2 | E5: 3 | F5: 5 | G5: 7 | H5: 9 | S5: Education VR Customization Services | T5: Our solution will be based on curriculum in geology and related earth science for most common lesson for elementary to secondary school. Some school want to customize their own curriculum for specific grades, we estimated that only very few schools initially will go for this service ~2 for first year. But once we launch our products and many schools/students tries our products then more and more schools will avail this service.
B6: Fee | D6: 1200 | E6: 1200 | F6: 1200 | G6: 1200 | H6: 1200
B7: No of visitors | C7: Stream 3 Visitors | D7: 400 | E7: 500 | F7: 600 | G7: 600 | H7: 600 | S7: Number of visitoers | T7: Since we are presenting this solution inside the mining 4IR center; and visitors are expected to visit the center for all developed application and presented technology. So, we have estimated yearly number of visitors for the center and divided for now by 3 applications income.
B8: Service fee | D8: 3 | E8: 3 | F8: 4 | G8: 4 | H8: 4
B9: Revenue | D9: =D3*D4+D5*D6+D7*D8 -> 15600 | E9: =E3*E4+E5*E6+E7*E8 -> 24900 | F9: =F3*F4+F5*F6+F7*F8 -> 45900 | G9: =G3*G4+G5*G6+G7*G8 -> 54000 | H9: =H3*H4+H5*H6+H7*H8 -> 67200 | I9: =I3*I4 -> 24000 | J9: =J3*J4 -> 24000 | K9: =K3*K4 -> 24000 | L9: =L3*L4 -> 24000 | M9: =M3*M4 -> 24000 | N9: =N3*N4 -> 24000 | O9: =O3*O4 -> 24000 | P9: =P3*P4 -> 24000 | Q9: =Q3*Q4 -> 24000
B11: Costs Included in COGS | S11: Costs Included in COGS | T11: Reason and logic for assumption | U11: Remarks if any
B12: Number of final devices required | D12: 10 | E12: 12 | F12: 12 | G12: 13 | H12: 15 | I12: 15 | J12: 15 | K12: 15 | L12: 15 | M12: 15 | N12: 15 | O12: 15 | P12: 15 | Q12: 15 | S12: Number of final devices required | T12: Reason and logic | U12: Total of 15 VR headset to be purchase for first Year and increase and replace for following years
I13: 6000 | J13: 6000 | K13: 6000 | L13: 6000 | M13: 6000 | N13: 6000 | O13: 6000 | P13: 6000 | Q13: 6000
I14: 100 | J14: 100 | K14: 100 | L14: 100 | M14: 100 | N14: 100 | O14: 100 | P14: 100 | Q14: 100
B15: Customer support | D15: 500 | E15: 500 | F15: 600 | G15: 600 | H15: 700 | I15: 100 | J15: 100 | K15: 100 | L15: 100 | M15: 100 | N15: 100 | O15: 100 | P15: 100 | Q15: 100 | S15: Customer support | T15: Reason and logic | U15: Estimated based on customers support calls
B16: Internal engineer support | D16: 100 | E16: 100 | F16: 100 | G16: 100 | H16: 100 | I16: 100 | J16: 100 | K16: 100 | L16: 100 | M16: 100 | N16: 100 | O16: 100 | P16: 100 | Q16: 100 | S16: Internal engineer support | T16: Reason and logic
B17: Other costs | D17: 1000 | E17: 1000 | F17: 1000 | G17: 1000 | H17: 1000 | I17: =200*I12 -> 3000 | J17: =200*J12 -> 3000 | K17: =200*K12 -> 3000 | L17: =200*L12 -> 3000 | M17: =200*M12 -> 3000 | N17: =200*N12 -> 3000 | O17: =200*O12 -> 3000 | P17: =200*P12 -> 3000 | Q17: =200*Q12 -> 3000 | S17: Other costs | T17: Reason and logic | U17: Backup cost/ Contingency every year 1,000 OMR for
B18: Supervision | D18: 100 | E18: 100 | F18: 100 | G18: 100 | H18: 100 | I18: 100 | J18: 100 | K18: 100 | L18: 100 | M18: 100 | N18: 100 | O18: 100 | P18: 100 | Q18: 100 | S18: Supervision | T18: Reason and logic
B19: Total COGS | D19: =SUM(D13:D18) -> 1700 | E19: =SUM(E13:E18) -> 1700 | F19: =SUM(F13:F18) -> 1800 | G19: =SUM(G13:G18) -> 1800 | H19: =SUM(H13:H18) -> 1900 | I19: =SUM(I13:I18) -> 9400 | J19: =SUM(J13:J18) -> 9400 | K19: =SUM(K13:K18) -> 9400 | ... Q19: =SUM(Q13:Q18) -> 9400
B21: Gross Profit | D21: =D9-D19 -> 13900 | E21: =E9-E19 -> 23200 | F21: =F9-F19 -> 44100 | G21: =G9-G19 -> 52200 | H21: =H9-H19 -> 65300 | I21: =I9-I19 -> 14600 | J21: =J9-J19 -> 14600 | K21: =K9-K19 -> 14600 | ... Q21: =Q9-Q19 -> 14600
B23: Production Overhead | S23: Production Overhead | T23: Reason and logic for assumption | U23: Remarks if any
B24: Rent of Production Premises | S24: Rent of Production Premises | T24: Reason and logic
B25: Non-Production Electricity | S25: Non-Production Electricity | T25: Reason and logic
B26: Staff Costs | S26: Staff Costs | T26: Reason and logic
B27: Production Maintenance | S27: Production Maintenance | T27: Reason and logic
B28: Carriage Inwards not in COGS | S28: Carriage Inwards not in COGS | T28: Reason and logic
B29: Labour (not used in Production) | S29: Labour (not used in Production) | T29: Reason and logic
B30: Total Production Overhead | D30: =SUM(D24:D29) -> 0 | E30: =SUM(E24:E29) -> 0 | F30: =SUM(F24:F29) -> 0 | G30: =SUM(G24:G29) -> 0 | H30: =SUM(H24:H29) -> 0 | I30: =SUM(I24:I29) -> 0 | J30: =SUM(J24:J29) -> 0 | K30: =SUM(K24:K29) -> 0 | ... Q30: =SUM(Q24:Q29) -> 0
B32: Selling and Admin Overhead Costs | S32: Selling and Admin Overhead Costs | T32: Reason and logic for assumption | U32: Remarks if any
B33: Rent | D33: 3600 | E33: 3600 | F33: 4800 | G33: 6000 | H33: 6000 | S33: Rent (Office only) | T33: Reason and logic | U33: Since the center facility will be used by all applications; then the yearly renting cost will be divided by 3. Example for first year the renting fees per month 900 OMR each application will contributes of 300 OMR per month for the rent. Per year 3600 OMR
B34: Warehouse rent | S34: Warehouse rent | T34: Reason and logic
B35: Logistics cost | S35: Logistics cost | T35: Reason and logic
B36: Management Salary | S36: Management Salary | T36: Reason and logic
B37: Staff Salary | S37: Staff Salary | T37: Reason and logic
B38: Labour Cost (ancillary) | S38: Labour Cost (ancillary) | T38: Reason and logic
B39: Electricity Cost | S39: Electricity Cost | T39: Reason and logic
B40: Administration costs | S40: Administration costs | T40: Reason and logic
B41: Water Cost | S41: Water Cost | T41: Reason and logic
B42: Fuel Cost | S42: Fuel Cost | T42: Reason and logic
B43: Telephone | S43: Telephone | T43: Reason and logic
B44: Internet | S44: Internet | T44: Reason and logic
B45: Travel / Flights | S45: Travel / Flights | T45: Reason and logic
...

Sheet Income Statement UAV
B2: Income Statement | D2: Year 1 | E2: Year 2 | F2: Year 3 | G2: Year 4 | H2: Year 5 | I2: Year 6 | J2: Year 7 | K2: Year 8 | L2: Year 9 | M2: Year 10 | N2: Year 11 | O2: Year 12 | P2: Year 13 | Q2: Year 14 | S2: Assumption | T2: Verfication of assumption | U2: Remarks if any
B3: Number of companies served | C3: Stream 1 Training HSE | D3: 8 | E3: 9 | F3: 15 | G3: 16 | H3: 20 | I3: 12 | J3: 12 | K3: 12 | L3: 12 | M3: 12 | N3: 12 | O3: 12 | P3: 12 | Q3: 12 | S3: Number of companies served | T3: How was it verified | U3: Since we estimated 20 number of major companies operating in mining in Oman and this report is mandatorey my the minstry, for first year we estimated 40% companies will avail our service, next year 45%
B4: service fee/company | D4: 1500 | E4: 2000 | F4: 2000 | G4: 2000 | H4: 2000 | I4: 2000 | J4: 2000 | K4: 2000 | L4: 2000 | M4: 2000 | N4: 2000 | O4: 2000 | P4: 2000 | Q4: 2000 | S4: service fee/company | T4: How was it verified | U4: We value our service as, if companies are mandated to conduct yearly environment report we value the services by our current drone inspection services. Where such services will cost 1500 OMR per report.
B5: No fo companies | C5: Stream 2 Customization | D5: 1 | E5: 1 | F5: 2 | G5: 2 | H5: 2 | S5: Drone Customization Services | T5: For first year we will be focusing on drone application for environmental monitoring, but some companies may request different drone services for mineral exploration, etc. But this is will be very limited for first years till the technology prove it concept and many companies relies on the value of drone to enhance their operation. For first year we estimated no request will company but for coming years will see increase in the requested of such service.
B6: Fee | D6: 2000 | E6: 2000 | F6: 2500 | G6: 2500 | H6: 2500
B7: No of visitors | C7: Stream 3 Visitors | D7: 400 | E7: 500 | F7: 600 | G7: 600 | H7: 600 | S7: Number of visitoers | T7: Since we are presenting this solution inside the mining 4IR center; and visitors are expected to visit the center for all developed application and presented technology. So, we have estimated yearly number of visitors for the center and divided for now by 3 applications income.
B8: Service fee | D8: 3 | E8: 3 | F8: 4 | G8: 4 | H8: 4
B9: Revenue | D9: =D3*D4+D5*D6+D7*D8 -> 15200 | E9: =E3*E4+E5*E6+E7*E8 -> 21500 | F9: =F3*F4+F5*F6+F7*F8 -> 37400 | G9: =G3*G4+G5*G6+G7*G8 -> 39400 | H9: =H3*H4+H5*H6+H7*H8 -> 47400 | I9: =I3*I4 -> 24000 | J9: =J3*J4 -> 24000 | K9: =K3*K4 -> 24000 | L9: =L3*L4 -> 24000 | M9: =M3*M4 -> 24000 | N9: =N3*N4 -> 24000 | O9: =O3*O4 -> 24000 | P9: =P3*P4 -> 24000 | Q9: =Q3*Q4 -> 24000
B11: Costs Included in COGS | S11: Costs Included in COGS | T11: Reason and logic for assumption | U11: Remarks if any
B12: Number of final devices required | D12: 1 | E12: 1 | F12: 1 | G12: 1 | H12: 1 | I12: 15 | J12: 15 | K12: 15 | L12: 15 | M12: 15 | N12: 15 | O12: 15 | P12: 15 | Q12: 15 | S12: Number of final devices required | T12: Reason and logic | U12: Total of 1 drone set of equipment to be purchase for first Year and add equipment and replace for following years
I13: 6000 | J13: 6000 | K13: 6000 | L13: 6000 | M13: 6000 | N13: 6000 | O13: 6000 | P13: 6000 | Q13: 6000
I14: 100 | J14: 100 | K14: 100 | L14: 100 | M14: 100 | N14: 100 | O14: 100 | P14: 100 | Q14: 100
B15: Customer support | D15: 500 | E15: 500 | F15: 600 | G15: 600 | H15: 700 | I15: 100 | J15: 100 | K15: 100 | L15: 100 | M15: 100 | N15: 100 | O15: 100 | P15: 100 | Q15: 100 | S15: Customer support | T15: Reason and logic | U15: Estimated based on customers support calls
B16: Internal engineer support | D16: 100 | E16: 100 | F16: 100 | G16: 100 | H16: 100 | I16: 100 | J16: 100 | K16: 100 | L16: 100 | M16: 100 | N16: 100 | O16: 100 | P16: 100 | Q16: 100 | S16: Internal engineer support | T16: Reason and logic
B17: Other costs | D17: 1000 | E17: 1000 | F17: 1000 | G17: 1000 | H17: 1000 | I17: =200*I12 -> 3000 | J17: =200*J12 -> 3000 | K17: =200*K12 -> 3000 | L17: =200*L12 -> 3000 | M17: =200*M12 -> 3000 | N17: =200*N12 -> 3000 | O17: =200*O12 -> 3000 | P17: =200*P12 -> 3000 | Q17: =200*Q12 -> 3000 | S17: Other costs | T17: Reason and logic | U17: Backup cost/ Contingency every year 1,000 OMR for
B18: Supervision | D18: 100 | E18: 100 | F18: 100 | G18: 100 | H18: 100 | I18: 100 | J18: 100 | K18: 100 | L18: 100 | M18: 100 | N18: 100 | O18: 100 | P18: 100 | Q18: 100 | S18: Supervision | T18: Reason and logic
B19: Total COGS | D19: =SUM(D13:D18) -> 1700 | E19: =SUM(E13:E18) -> 1700 | F19: =SUM(F13:F18) -> 1800 | G19: =SUM(G13:G18) -> 1800 | H19: =SUM(H13:H18) -> 1900 | I19: =SUM(I13:I18) -> 9400 | J19: =SUM(J13:J18) -> 9400 | K19: =SUM(K13:K18) -> 9400 | ... Q19: =SUM(Q13:Q18) -> 9400
B21: Gross Profit | D21: =D9-D19 -> 13500 | E21: =E9-E19 -> 19800 | F21: =F9-F19 -> 35600 | G21: =G9-G19 -> 37600 | H21: =H9-H19 -> 45500 | I21: =I9-I19 -> 14600 | J21: =J9-J19 -> 14600 | K21: =K9-K19 -> 14600 | ... Q21: =Q9-Q19 -> 14600
B23: Production Overhead | S23: Production Overhead | T23: Reason and logic for assumption | U23: Remarks if any
B24: Rent of Production Premises | S24: Rent of Production Premises | T24: Reason and logic
B25: Non-Production Electricity | S25: Non-Production Electricity | T25: Reason and logic
B26: Staff Costs | S26: Staff Costs | T26: Reason and logic
B27: Production Maintenance | S27: Production Maintenance | T27: Reason and logic
B28: Carriage Inwards not in COGS | S28: Carriage Inwards not in COGS | T28: Reason and logic
B29: Labour (not used in Production) | S29: Labour (not used in Production) | T29: Reason and logic
B30: Total Production Overhead | D30: =SUM(D24:D29) -> 0 | E30: =SUM(E24:E29) -> 0 | F30: =SUM(F24:F29) -> 0 | G30: =SUM(G24:G29) -> 0 | H30: =SUM(H24:H29) -> 0 | I30: =SUM(I24:I29) -> 0 | J30: =SUM(J24:J29) -> 0 | K30: =SUM(K24:K29) -> 0 | ... Q30: =SUM(Q24:Q29) -> 0
B32: Selling and Admin Overhead Costs | S32: Selling and Admin Overhead Costs | T32: Reason and logic for assumption | U32: Remarks if any
B33: Rent | D33: 3600 | E33: 3600 | F33: 4800 | G33: 6000 | H33: 6000 | S33: Rent (Office only) | T33: Reason and logic | U33: Since the center facility will be used by all applications; then the yearly renting cost will be divided by 3. Example for first year the renting fees per month 900 OMR each application will contributes of 300 OMR per month for the rent. Per year 3600 OMR
B34: Warehouse rent | S34: Warehouse rent | T34: Reason and logic
B35: Logistics cost | S35: Logistics cost | T35: Reason and logic
B36: Management Salary | S36: Management Salary | T36: Reason and logic
B37: Staff Salary | S37: Staff Salary | T37: Reason and logic
B38: Labour Cost (ancillary) | S38: Labour Cost (ancillary) | T38: Reason and logic
B39: Electricity Cost | S39: Electricity Cost | T39: Reason and logic
B40: Administration costs | S40: Administration costs | T40: Reason and logic
B41: Water Cost | S41: Water Cost | T41: Reason and logic
B42: Fuel Cost | S42: Fuel Cost | T42: Reason and logic
B43: Telephone | S43: Telephone | T43: Reason and logic
B44: Internet | S44: Internet | T44: Reason and logic
B45: Travel / Flights | S45: Travel / Flights | T45: Reason and logic
...

Sheet Cashflow
B3: Cashflow | C3: Year 1 | D3: Year 2 | E3: Year 3 | F3: Year 4 | G3: Year 5 | H3: Year 6 | I3: Year 7 | J3: Year 8 | K3: Year 9 | L3: Year 10 | M3: Year 11 | N3: Year 12 | O3: Year 13 | P3: Year 14
B4: Cashflow from operation
B5: Net income (income statement) | C5: ='Income Statement exp Summary'!D67 -> 4064.3333 | D5: ='Income Statement exp Summary'!E67 -> 39155.667 | E5: ='Income Statement exp Summary'!F67 -> 74011 | F5: ='Income Statement exp Summary'!G67 -> 86782.667 | G5: ='Income Statement exp Summary'!H67 -> 110935.67 | H5: ='Income Statement exp Summary'!I67 -> #REF! | I5: ='Income Statement exp Summary'!J67 -> #REF! | J5: ='Income Statement exp Summary'!K67 -> #REF! | ... P5: ='Income Statement exp Summary'!Q67 -> #REF!
B6: Additions to cashflow | C6: =SUM(C7:C8) -> 3166.6667 | D6: =SUM(D7:D8) -> 4333.3333 | E6: =SUM(E7:E8) -> 5500 | F6: =SUM(F7:F8) -> 4333.3333 | G6: =SUM(G7:G8) -> 4333.3333 | H6: =SUM(H7:H8) -> #REF! | I6: =SUM(I7:I8) -> #REF! | J6: =SUM(J7:J8) -> #REF! | ... P6: =SUM(P7:P8) -> #REF!
B7: Depreciation | C7: ='Income Statement exp Summary'!D61 -> 3166.6667 | D7: ='Income Statement exp Summary'!E61 -> 4333.3333 | E7: ='Income Statement exp Summary'!F61 -> 5500 | F7: ='Income Statement exp Summary'!G61 -> 4333.3333 | G7: ='Income Statement exp Summary'!H61 -> 4333.3333 | H7: ='Income Statement exp Summary'!I61 -> #REF! | I7: ='Income Statement exp Summary'!J61 -> #REF! | J7: ='Income Statement exp Summary'!K61 -> #REF! | ... P7: ='Income Statement exp Summary'!Q61 -> #REF!
B8: Increase in accounts payable
B9: Subtraction from cashflow | C9: =SUM(C10:C11) -> 0 | D9: =SUM(D10:D11) -> 0 | E9: =SUM(E10:E11) -> 0 | F9: =SUM(F10:F11) -> 0 | G9: =SUM(G10:G11) -> 0 | H9: =SUM(H10:H11) -> 0 | I9: =SUM(I10:I11) -> 0 | J9: =SUM(J10:J11) -> 0 | ... P9: =SUM(P10:P11) -> 0
B10: Increase in accounts receivable
B11: Increase in inventory
B12: Net cash from operations | C12: =C5+C6-C9 -> 7231 | D12: =D5+D6-D9 -> 43489 | E12: =E5+E6-E9 -> 79511 | F12: =F5+F6-F9 -> 91116 | G12: =G5+G6-G9 -> 115269 | H12: =H5+H6-H9 -> #REF! | I12: =I5+I6-I9 -> #REF! | J12: =J5+J6-J9 -> #REF! | ... P12: =P5+P6-P9 -> #REF!
B13: Cash flow from investing | C13: =C14 -> 9500 | D13: =D14 -> 3500 | E13: =E14 -> 3500 | F13: =F14 -> 6000 | G13: =G14 -> 3500 | H13: =H14 -> 0 | I13: =I14 -> 0 | J13: =J14 -> 0 | ... P13: =P14 -> 0
B14: Purchase of equipment | C14: ='Income Statement exp Summary'!D74 -> 9500 | D14: ='Income Statement exp Summary'!E74 -> 3500 | E14: ='Income Statement exp Summary'!F74 -> 3500 | F14: ='Income Statement exp Summary'!G74 -> 6000 | G14: ='Income Statement exp Summary'!H74 -> 3500
B15: Cash flow from financing | C15: =C16 -> 0 | D15: =D16 -> 0 | E15: =E16 -> 0 | F15: =F16 -> 0 | G15: =G16 -> 0 | H15: =H16 -> 0 | I15: =I16 -> 0 | J15: =J16 -> 0 | ... P15: =P16 -> 0
B16: Notes payable(loan from bank)
B17: Net Cashflow | C17: =C12-C13+C15 -> -2269 | D17: =D12-D13+D15 -> 39989 | E17: =E12-E13+E15 -> 76011 | F17: =F12-F13+F15 -> 85116 | G17: =G12-G13+G15 -> 111769 | H17: =H12-H13+H15 -> #REF! | I17: =I12-I13+I15 -> #REF! | J17: =J12-J13+J15 -> #REF! | ... P17: =P12-P13+P15 -> #REF!
B19: Total Revenue | C19: ='Income Statement exp Summary'!D9 -> 42900 | D19: ='Income Statement exp Summary'!E9 -> 69700 | E19: ='Income Statement exp Summary'!F9 -> 112700 | F19: ='Income Statement exp Summary'!G9 -> 126800 | G19: ='Income Statement exp Summary'!H9 -> 152000
B20: Total cost required | C20: ='Income Statement exp Summary'!D19+'Income Statement exp Summary'!D56+'Income Statement exp Summary'!D74 -> 45000 | D20: ='Income Statement exp Summary'!E19+'Income Statement exp Summary'!E56+'Income Statement exp Summary'!E74 -> 28500 | E20: ='Income Statement exp Summary'!F19+'Income Statement exp Summary'!F56+'Income Statement exp Summary'!F74 -> 34400 | F20: ='Income Statement exp Summary'!G19+'Income Statement exp Summary'!G56+'Income Statement exp Summary'!G74 -> 39000 | G20: ='Income Statement exp Summary'!H19+'Income Statement exp Summary'!H56+'Income Statement exp Summary'!H74 -> 36800
B21: Net Cashflow | C21: =C17 -> -2269 | D21: =D17 -> 39989 | E21: =E17 -> 76011 | F21: =F17 -> 85116 | G21: =G17 -> 111769
