Workbook

Sheet Revenue Optimization simulation
D1: Business Channel (Select dropdown Menue), Set Scores & Calculate Charges | N1: Charges
A2: Investment Strength Matrix | B2: Score Points | D2: Royalty | E2: Fees | F2: spinoff | G2: Franchise | H2: Other | N2: Royalty | O2: Fees | P2: spinoff | Q2: Franchise | R2: Other
A3: Strength of idea/ Concept: O- 5 × 5 OMR | B3: 1 to 5*1 | D3: =5*1 -> 5 | E3: =5*1 -> 5 | F3: =5*1 -> 5 | G3: =5*1 -> 5 | N3: =$B$3*D3 -> #VALUE! | O3: =$B$3*E3 -> #VALUE! | P3: =$B$3*F3 -> #VALUE! | Q3: =$B$3*G3 -> #VALUE! | R3: =$B$3*H3 -> #VALUE!
A4: Prototype readiness for commercialisation: 0-5×10 OMR | B4: 1 to 5*2 | D4: =4*2 -> 8 | E4: =4*2 -> 8 | F4: =4*2 -> 8 | G4: =4*2 -> 8 | N4: =$B$4*D4 -> #VALUE! | O4: =$B$4*E4 -> #VALUE! | P4: =$B$4*F4 -> #VALUE! | Q4: =$B$4*G4 -> #VALUE! | R4: =$B$4*H4 -> #VALUE!
A5: Piloting Scale :0-5 × 100 | B5: 1 to 5*3 | D5: =4*3 -> 12 | E5: =4*3 -> 12 | F5: =4*3 -> 12 | G5: =4*3 -> 12 | N5: =$B$5*D5 -> #VALUE! | O5: =$B$5*E5 -> #VALUE! | P5: =$B$5*F5 -> #VALUE! | Q5: =$B$5*G5 -> #VALUE! | R5: =$B$5*H5 -> #VALUE!
A6: Franchising : 0-5× 1000 | B6: 1 to 5 | D6: 4 | E6: 4 | F6: 4 | G6: 4 | N6: =$B$6*D6 -> #VALUE! | O6: =$B$6*E6 -> #VALUE! | P6: =$B$6*F6 -> #VALUE! | Q6: =$B$6*G6 -> #VALUE! | R6: =$B$6*H6 -> #VALUE!
A7: IP Strength : 0 × 5 × 100 OMR | B7: 1 to 5*5 | D7: =4*5 -> 20 | E7: =4*5 -> 20 | F7: =4*5 -> 20 | G7: =4*5 -> 20 | N7: =$B$7*D7 -> #VALUE! | O7: =$B$7*E7 -> #VALUE! | P7: =$B$7*F7 -> #VALUE! | Q7: =$B$7*G7 -> #VALUE! | R7: =$B$7*H7 -> #VALUE!
A8: Branding readiness :0-5 × 100 OMR | B8: 1 to 5*5 | D8: =4*5 -> 20 | E8: =4*5 -> 20 | F8: =2*5 -> 10 | G8: =4*5 -> 20 | N8: =$B$8*D8 -> #VALUE! | O8: =$B$8*E8 -> #VALUE! | P8: =$B$8*F8 -> #VALUE! | Q8: =$B$8*G8 -> #VALUE! | R8: =$B$8*H8 -> #VALUE!
A9: commercialisation Readiness: 0-5×100 OMR | B9: 1 to 5*10 | D9: =4*10 -> 40 | E9: =4*10 -> 40 | F9: =4*10 -> 40 | G9: =4*10 -> 40 | N9: =$B$9*D9 -> #VALUE! | O9: =$B$9*E9 -> #VALUE! | P9: =$B$9*F9 -> #VALUE! | Q9: =$B$9*G9 -> #VALUE! | R9: =$B$9*H9 -> #VALUE!
A10: Exclusivity: :0-5×100 OMR | B10: 1 to 5*100 | D10: =0*100 -> 0 | E10: =5*100 -> 500 | F10: =1*100 -> 100 | G10: =5*100 -> 500 | N10: =$B$10*D10 -> #VALUE! | O10: =$B$10*E10 -> #VALUE! | P10: =$B$10*F10 -> #VALUE! | Q10: =$B$10*G10 -> #VALUE! | R10: =$B$10*H10 -> #VALUE!
A11: Total score = | D11: =SUM(D3:D10) -> 109 | E11: =SUM(E3:E10) -> 609 | F11: =SUM(F3:F10) -> 199 | G11: =SUM(G3:G10) -> 609 | H11: =SUM(H3:H10) -> 0
A12: Total Charges = | D12: =D11 -> 109 | E12: =E11 -> 609 | F12: =F11 -> 199 | G12: =G11 -> 609 | H12: =H11 -> 0 | N12: =SUM(N3:N10) -> #VALUE! | O12: =SUM(O3:O10) -> #VALUE! | P12: =SUM(P3:P10) -> #VALUE! | Q12: =SUM(Q3:Q10) -> #VALUE! | R12: =SUM(R3:R10) -> #VALUE!
A14: Targetted Markets
A15: Customers | D15: Commercialization Channels- Targetted Number of Customers | K15: Revenue | N15: Commercialization Channels-Revenue(in OMR)
A16: Region | B16: Segments | C16: Partners | D16: Royalty | E16: Fees | F16: spinoff | G16: Franchise | H16: Other | I16: Total Revenues | K16: Region | L16: Channel | M16: Partners | N16: Royalty | O16: Fees | P16: spinoff | Q16: Franchise | R16: Other | S16: Total
A17: Oman | B17: Segment 1 | C17: Partners1 | D17: 10 | E17: 10 | F17: 10 | G17: 10 | H17: 10 | I17: =SUM(D17:H17) -> 50 | K17: Oman | L17: Segment 1 | M17: Partners1 | N17: =D17*N$12 -> #VALUE! | O17: =E17*O$12 -> #VALUE! | P17: =F17*P$12 -> #VALUE! | Q17: =G17*Q$12 -> #VALUE! | R17: =H17*R$12 -> #VALUE! | S17: =SUM(N17:R17) -> #VALUE!
C18: Partners2 | D18: 20 | E18: 20 | F18: 20 | G18: 20 | H18: 20 | I18: =SUM(D18:H18) -> 100 | M18: Partners2 | N18: =D18*N$12 -> #VALUE! | O18: =E18*O$12 -> #VALUE! | P18: =F18*P$12 -> #VALUE! | Q18: =G18*Q$12 -> #VALUE! | R18: =H18*R$12 -> #VALUE! | S18: =SUM(N18:R18) -> #VALUE!
C19: Partners3 | D19: 30 | E19: 30 | F19: 30 | G19: 30 | H19: 30 | I19: =SUM(D19:H19) -> 150 | M19: Partners3 | N19: =D19*N$12 -> #VALUE! | O19: =E19*O$12 -> #VALUE! | P19: =F19*P$12 -> #VALUE! | Q19: =G19*Q$12 -> #VALUE! | R19: =H19*R$12 -> #VALUE! | S19: =SUM(N19:R19) -> #VALUE!
B20: Segment 2 | C20: Partners4 | D20: 10 | E20: 10 | F20: 10 | G20: 10 | H20: 10 | I20: =SUM(D20:H20) -> 50 | L20: Segment 2 | M20: Partners4 | N20: =D20*N$12 -> #VALUE! | O20: =E20*O$12 -> #VALUE! | P20: =F20*P$12 -> #VALUE! | Q20: =G20*Q$12 -> #VALUE! | R20: =H20*R$12 -> #VALUE! | S20: =SUM(N20:R20) -> #VALUE!
C21: Partners5 | D21: 20 | E21: 20 | F21: 20 | G21: 20 | H21: 20 | I21: =SUM(D21:H21) -> 100 | M21: Partners5 | N21: =D21*N$12 -> #VALUE! | O21: =E21*O$12 -> #VALUE! | P21: =F21*P$12 -> #VALUE! | Q21: =G21*Q$12 -> #VALUE! | R21: =H21*R$12 -> #VALUE! | S21: =SUM(N21:R21) -> #VALUE!
C22: Partners6 | D22: 30 | E22: 30 | F22: 30 | G22: 30 | H22: 30 | I22: =SUM(D22:H22) -> 150 | M22: Partners6 | N22: =D22*N$12 -> #VALUE! | O22: =E22*O$12 -> #VALUE! | P22: =F22*P$12 -> #VALUE! | Q22: =G22*Q$12 -> #VALUE! | R22: =H22*R$12 -> #VALUE! | S22: =SUM(N22:R22) -> #VALUE!
B23: Segment3 | C23: Partners7 | D23: 10 | E23: 10 | F23: 10 | G23: 10 | H23: 10 | I23: =SUM(D23:H23) -> 50 | L23: Segment3 | M23: Partners7 | N23: =D23*N$12 -> #VALUE! | O23: =E23*O$12 -> #VALUE! | P23: =F23*P$12 -> #VALUE! | Q23: =G23*Q$12 -> #VALUE! | R23: =H23*R$12 -> #VALUE! | S23: =SUM(N23:R23) -> #VALUE!
C24: Partners8 | D24: 20 | E24: 20 | F24: 20 | G24: 20 | H24: 20 | I24: =SUM(D24:H24) -> 100 | M24: Partners8 | N24: =D24*N$12 -> #VALUE! | O24: =E24*O$12 -> #VALUE! | P24: =F24*P$12 -> #VALUE! | Q24: =G24*Q$12 -> #VALUE! | R24: =H24*R$12 -> #VALUE! | S24: =SUM(N24:R24) -> #VALUE!
C25: Partners9 | D25: 30 | E25: 30 | F25: 30 | G25: 30 | H25: 30 | I25: =SUM(D25:H25) -> 150 | M25: Partners9 | N25: =D25*N$12 -> #VALUE! | O25: =E25*O$12 -> #VALUE! | P25: =F25*P$12 -> #VALUE! | Q25: =G25*Q$12 -> #VALUE! | R25: =H25*R$12 -> #VALUE! | S25: =SUM(N25:R25) -> #VALUE!
A26: Total-Oman | D26: =SUM(D17:D25) -> 180 | E26: =SUM(E17:E25) -> 180 | F26: =SUM(F17:F25) -> 180 | G26: =SUM(G17:G25) -> 180 | H26: =SUM(H17:H25) -> 180 | I26: =SUM(I17:I25) -> 900 | K26: Total-Oman | N26: =SUM(N17:N25) -> #VALUE! | O26: =SUM(O17:O25) -> #VALUE! | P26: =SUM(P17:P25) -> #VALUE! | Q26: =SUM(Q17:Q25) -> #VALUE! | R26: =SUM(R17:R25) -> #VALUE! | S26: =SUM(S17:S25) -> #VALUE!
A27: Iran | B27: Segment 1 | C27: Partners1 | D27: 10 | E27: 10 | F27: 10 | G27: 10 | H27: 10 | I27: =SUM(D27:H27) -> 50 | K27: Iran | L27: Segment 1 | M27: Partners1 | N27: =D27*N$12 -> #VALUE! | O27: =E27*O$12 -> #VALUE! | P27: =F27*P$12 -> #VALUE! | Q27: =G27*Q$12 -> #VALUE! | R27: =H27*R$12 -> #VALUE! | S27: =SUM(N27:R27) -> #VALUE!
C28: Partners2 | D28: 20 | E28: 20 | F28: 20 | G28: 20 | H28: 20 | I28: =SUM(D28:H28) -> 100 | M28: Partners2 | N28: =D28*N$12 -> #VALUE! | O28: =E28*O$12 -> #VALUE! | P28: =F28*P$12 -> #VALUE! | Q28: =G28*Q$12 -> #VALUE! | R28: =H28*R$12 -> #VALUE! | S28: =SUM(N28:R28) -> #VALUE!
C29: Partners3 | D29: 30 | E29: 30 | F29: 30 | G29: 30 | H29: 30 | I29: =SUM(D29:H29) -> 150 | M29: Partners3 | N29: =D29*N$12 -> #VALUE! | O29: =E29*O$12 -> #VALUE! | P29: =F29*P$12 -> #VALUE! | Q29: =G29*Q$12 -> #VALUE! | R29: =H29*R$12 -> #VALUE! | S29: =SUM(N29:R29) -> #VALUE!
B30: Segment 2 | C30: Partners4 | D30: 10 | E30: 10 | F30: 10 | G30: 10 | H30: 10 | I30: =SUM(D30:H30) -> 50 | L30: Segment 2 | M30: Partners4 | N30: =D30*N$12 -> #VALUE! | O30: =E30*O$12 -> #VALUE! | P30: =F30*P$12 -> #VALUE! | Q30: =G30*Q$12 -> #VALUE! | R30: =H30*R$12 -> #VALUE! | S30: =SUM(N30:R30) -> #VALUE!
C31: Partners5 | D31: 20 | E31: 20 | F31: 20 | G31: 20 | H31: 20 | I31: =SUM(D31:H31) -> 100 | M31: Partners5 | N31: =D31*N$12 -> #VALUE! | O31: =E31*O$12 -> #VALUE! | P31: =F31*P$12 -> #VALUE! | Q31: =G31*Q$12 -> #VALUE! | R31: =H31*R$12 -> #VALUE! | S31: =SUM(N31:R31) -> #VALUE!
C32: Partners6 | D32: 30 | E32: 30 | F32: 30 | G32: 30 | H32: 30 | I32: =SUM(D32:H32) -> 150 | M32: Partners6 | N32: =D32*N$12 -> #VALUE! | O32: =E32*O$12 -> #VALUE! | P32: =F32*P$12 -> #VALUE! | Q32: =G32*Q$12 -> #VALUE! | R32: =H32*R$12 -> #VALUE! | S32: =SUM(N32:R32) -> #VALUE!
B33: Segment3 | C33: Partners7 | D33: 10 | E33: 10 | F33: 10 | G33: 10 | H33: 10 | I33: =SUM(D33:H33) -> 50 | L33: Segment3 | M33: Partners7 | N33: =D33*N$12 -> #VALUE! | O33: =E33*O$12 -> #VALUE! | P33: =F33*P$12 -> #VALUE! | Q33: =G33*Q$12 -> #VALUE! | R33: =H33*R$12 -> #VALUE! | S33: =SUM(N33:R33) -> #VALUE!
C34: Partners8 | D34: 20 | E34: 20 | F34: 20 | G34: 20 | H34: 20 | I34: =SUM(D34:H34) -> 100 | M34: Partners8 | N34: =D34*N$12 -> #VALUE! | O34: =E34*O$12 -> #VALUE! | P34: =F34*P$12 -> #VALUE! | Q34: =G34*Q$12 -> #VALUE! | R34: =H34*R$12 -> #VALUE! | S34: =SUM(N34:R34) -> #VALUE!
C35: Partners9 | D35: 30 | E35: 30 | F35: 30 | G35: 30 | H35: 30 | I35: =SUM(D35:H35) -> 150 | M35: Partners9 | N35: =D35*N$12 -> #VALUE! | O35: =E35*O$12 -> #VALUE! | P35: =F35*P$12 -> #VALUE! | Q35: =G35*Q$12 -> #VALUE! | R35: =H35*R$12 -> #VALUE! | S35: =SUM(N35:R35) -> #VALUE!
A36: Total-Iran | D36: =SUM(D27:D35) -> 180 | E36: =SUM(E27:E35) -> 180 | F36: =SUM(F27:F35) -> 180 | G36: =SUM(G27:G35) -> 180 | H36: =SUM(H27:H35) -> 180 | I36: =SUM(I27:I35) -> 900 | K36: Total-Iran | N36: =SUM(N27:N35) -> #VALUE! | O36: =SUM(O27:O35) -> #VALUE! | P36: =SUM(P27:P35) -> #VALUE! | Q36: =SUM(Q27:Q35) -> #VALUE! | R36: =SUM(R27:R35) -> #VALUE! | S36: =SUM(S27:S35) -> #VALUE!
A37: Malaysia | B37: Segment 1 | C37: Partners1 | D37: 10 | E37: 10 | F37: 10 | G37: 10 | H37: 10 | I37: =SUM(D37:H37) -> 50 | K37: Malaysia | L37: Segment 1 | M37: Partners1 | N37: =D37*N$12 -> #VALUE! | O37: =E37*O$12 -> #VALUE! | P37: =F37*P$12 -> #VALUE! | Q37: =G37*Q$12 -> #VALUE! | R37: =H37*R$12 -> #VALUE! | S37: =SUM(N37:R37) -> #VALUE!
C38: Partners2 | D38: 20 | E38: 20 | F38: 20 | G38: 20 | H38: 20 | I38: =SUM(D38:H38) -> 100 | M38: Partners2 | N38: =D38*N$12 -> #VALUE! | O38: =E38*O$12 -> #VALUE! | P38: =F38*P$12 -> #VALUE! | Q38: =G38*Q$12 -> #VALUE! | R38: =H38*R$12 -> #VALUE! | S38: =SUM(N38:R38) -> #VALUE!
C39: Partners3 | D39: 30 | E39: 30 | F39: 30 | G39: 30 | H39: 30 | I39: =SUM(D39:H39) -> 150 | M39: Partners3 | N39: =D39*N$12 -> #VALUE! | O39: =E39*O$12 -> #VALUE! | P39: =F39*P$12 -> #VALUE! | Q39: =G39*Q$12 -> #VALUE! | R39: =H39*R$12 -> #VALUE! | S39: =SUM(N39:R39) -> #VALUE!
B40: Segment 2 | C40: Partners4 | D40: 10 | E40: 10 | F40: 10 | G40: 10 | H40: 10 | I40: =SUM(D40:H40) -> 50 | L40: Segment 2 | M40: Partners4 | N40: =D40*N$12 -> #VALUE! | O40: =E40*O$12 -> #VALUE! | P40: =F40*P$12 -> #VALUE! | Q40: =G40*Q$12 -> #VALUE! | R40: =H40*R$12 -> #VALUE! | S40: =SUM(N40:R40) -> #VALUE!
C41: Partners5 | D41: 20 | E41: 20 | F41: 20 | G41: 20 | H41: 20 | I41: =SUM(D41:H41) -> 100 | M41: Partners5 | N41: =D41*N$12 -> #VALUE! | O41: =E41*O$12 -> #VALUE! | P41: =F41*P$12 -> #VALUE! | Q41: =G41*Q$12 -> #VALUE! | R41: =H41*R$12 -> #VALUE! | S41: =SUM(N41:R41) -> #VALUE!
...

Sheet Sheet1
A1: Section 1 | B1: Commercialisation Model: dropdown | F1: Should include all necessary sections of innovation driven businesses
B2: Royalty | E2: Innovation Canvas | F2: Section 1 | G2: Customer Segments
B3: Fees | E3: 15 elements(incluidng commercualization feasi8nbility matrix) | F3: Section 2 | G3: Value propositions | I3: Revenue stream | J3: Price from matrix | K3: targeted customers
B4: spinoff | F4: Section 3 | G4: Channels | I4: Revenue stream
B5: Franchise | F5: Section 4 | G5: Customer relationships | I5: Revenue stream
F6: Section 5 | G6: key actvities
F7: Section 6 | G7: Key resources
F8: Section 7 | G8: Key partnerships
A9: Section 2 | B9: Commercialisation Feasibility Matrix | E9: Feasibility | F9: Section 8 | G9: Feasibility matrix--pricing | H9: Revenue Streams
B10: Strength of idea/ Concept: O- 5 × 5 OMR | F10: Section 9 | G10: Number of customers
B11: Prototype readiness for commercialisation: 0-5×10 OMR | F11: Section 10 | G11: Costs
B12: Piloting Scale :0-5 × 100 | F12: Section 11 | G12: Financial Plan | H12: Revenue | I12: COGS | J12: GP | K12: Op ex | L12: Net profit | M12: ROI | N12: Breakeven
B13: Franchising : 0-5× 1000 | G13: Revenue
B14: IP Strength : 0 × 5 × 100 OMR
B15: Branding readiness :0-5 × 100 OMR | E15: Innovation Canvas---> Innovation feasibility--->Innovation commercialization plan
B16: commercialisation Readiness: 0-5×100 OMR
B17: Exclusivity: :0-5×100 OMR | I17: Progress 0 | J17: Progress 1 | K17: Progress 2 | L17: Progress 3 | M17: Progress 4 | N17: Progress 5 | O17: Progress 6 | P17: Progress 7 | Q17: Progress 8 | R17: Progress 9 | S17: Progress 10
B18: Total score = | H18: Understanding | I18: 0 | J18: 10 | K18: 20 | L18: 30 | M18: 40 | N18: 50 | O18: 60 | P18: 70 | Q18: 80 | R18: 90 | S18: 100
B19: Total Charges = | I19: Customer Segments | J19: Customer Segments | K19: Customer Segments | L19: Customer Segments | M19: Customer Segments | N19: Customer Segments | O19: Customer Segments | P19: Customer Segments | Q19: Customer Segments | R19: Customer Segments | S19: Customer Segments
A21: Section 3 | B21: Shares for Mediating Agencies | E21: Simulation | F21: Key Partnerships
B22: Linking & Bridging = 10,20,30% of Royality Charges | F22: Key Partnerships
B23: Maintenance & Improvement 10,20,30% of Royality Charge
A24: Setcion 4 | B24: KPIs & Targets
B25: Revenue | F25: Revenue stream
B26: ROI
B27: Break-Even analysis
A29: Section 5 | B29: Approval
A31: Section 6 | B31: Provisional
A33: Section 7 | B33: Tabulated clients list
B34: Individual or Entity
B35: Name
B36: Package System
B37: Royality Fees
B38: Payment Mode (monthly or Annual)
B39: Provisional field
B40: Provisional

Sheet original
B1: Section 1: Innovation Canvas
C2: Customer Segments(name) | D2: Job Seekers (Fresh Graduates) | E2: 3 Million OMR
D3: Skilled Professionals | E3: 4 Million OMR
D4: Employers & Companies (SMEs, Corporates) | E4: 6 Million OMR
D5: Recruitment Agencies | E5: 2 Million OMR
D6: Other Segments | E6: 2 Million OMR
C7: Value Propositions(name) | D7: AI-Powered Job Matching | E7: Uses AI to match job seekers with relevant job postings based on skills and experience.
D8: Verified Employer Listings | E8: Ensures job listings are authentic and from credible companies.
D9: Career Development & Upskilling | E9: Provides online courses, resume-building tools, and interview coaching.
D10: Seamless Hiring Process | E10: Employers can streamline recruitment with automated shortlisting and scheduling.
C11: Sales Channels(eg. Distributor, direct,none) | D11: Direct Sales | E11: Subscription-based plans for employers and recruiters.
D12: Online Platform | E12: Web and mobile app for job seekers and recruiters.
D13: Partnerships | E13: Collaboration with universities, training centers, and businesses
D14: Other Channels
C15: Customer Relationships(example service call center/email/whatsapp) | D15: 24/7 Live Chat Support | E15: Instant help for job seekers and employers.
D16: WhatsApp & Email Support | E16: Easy access to customer support for queries.
D17: Community Engagement | E17: Online forums, blogs, and networking events for career advice.
D18: Other Customer Relationship
C19: Key Activities(name) | D19: Platform Development | E19: Building and maintaining the web & mobile application.
D20: Job Listings Management | E20: Verifying employer job postings and monitoring fake listings.
D21: AI Job Matching | E21: Implementing and refining AI algorithms for better job recommendations.
D22: Marketing & Outreach | E22: Digital marketing campaigns to attract job seekers and employers.
C23: Key Resources(name) | D23: Software Developers | E23: 80,000 OMR annually
D24: AI Algorithms | E24: 25,000 OMR research & development
D25: Marketing & Branding | E25: 40,000 OMR per year
D26: Customer Support Team | E26: 30,000 OMR annually
C27: Key Partnerships(name) | D27: Universities & Training Centers | E27: Collaboration to help fresh graduates find jobs and improve skills.
D28: Corporate Employers | E28: Partnerships to list verified job openings and internships.
D29: Government Agencies | E29: Working with labor and employment ministries for regulatory compliance.
D30: Recruitment Agencies | E30: Integrating their job postings and hiring services into the platform.
E31: Projected Revenue (in OMR)
C32: Revenue Streams | D32: Royalty | E32: 1000
D33: Fees | E33: 1000
D34: spinoff | E34: 1000
D35: Franchise | E35: 1000
D36: Other | E36: 1000
D37: Total | E37: =SUM(E32:E36) -> 5000
C38: Cost Structure | D38: COGS/Cost of Sales for Royalty | E38: 400
D39: COGS/Cost of Sales for Fees | E39: 400
D40: COGS/Cost of Sales for spinoff | E40: 400
...

Sheet copy
A1: Section | B1: Field Name | C1: Value1 | D1: Value2
A2: Innovation Canvas | B2: segments | C2: Job Seekers (Fresh Graduates) | D2: 3 Million OMR
A3: Innovation Canvas | B3: Customer Segments(name) | C3: Skilled Professionals | D3: 4 Million OMR
A4: Innovation Canvas | B4: Customer Segments(name) | C4: Employers & Companies (SMEs, Corporates) | D4: 6 Million OMR
A5: Innovation Canvas | B5: Customer Segments(name) | C5: Recruitment Agencies | D5: 2 Million OMR
A6: Innovation Canvas | B6: Customer Segments(name) | C6: Other Segments | D6: 2 Million OMR
A7: Innovation Canvas | B7: Value Propositions(name) | C7: AI-Powered Job Matching | D7: Uses AI to match job seekers with relevant job postings based on skills and experience.
A8: Innovation Canvas | B8: Value Propositions(name) | C8: Verified Employer Listings | D8: Ensures job listings are authentic and from credible companies.
A9: Innovation Canvas | B9: Value Propositions(name) | C9: Career Development & Upskilling | D9: Provides online courses, resume-building tools, and interview coaching.
A10: Innovation Canvas | B10: Value Propositions(name) | C10: Seamless Hiring Process | D10: Employers can streamline recruitment with automated shortlisting and scheduling.
A11: Innovation Canvas | B11: Sales Channels(eg. Distributor, direct,none) | C11: Direct Sales | D11: Subscription-based plans for employers and recruiters.
A12: Innovation Canvas | B12: Sales Channels(eg. Distributor, direct,none) | C12: Online Platform | D12: Web and mobile app for job seekers and recruiters.
A13: Innovation Canvas | B13: Sales Channels(eg. Distributor, direct,none) | C13: Partnerships | D13: Collaboration with universities, training centers, and businesses
A14: Innovation Canvas | B14: Sales Channels(eg. Distributor, direct,none) | C14: Other Channels
A15: Innovation Canvas | B15: Customer Relationships | C15: 24/7 Live Chat Support | D15: Instant help for job seekers and employers.
A16: Innovation Canvas | B16: Customer Relationships | C16: WhatsApp & Email Support | D16: Easy access to customer support for queries.
A17: Innovation Canvas | B17: Customer Relationships | C17: Community Engagement | D17: Online forums, blogs, and networking events for career advice.
A18: Innovation Canvas | B18: Customer Relationships | C18: Other Customer Relationship
A19: Innovation Canvas | B19: Key Activities(name) | C19: Platform Development | D19: Building and maintaining the web & mobile application.
A20: Innovation Canvas | B20: Key Activities(name) | C20: Job Listings Management | D20: Verifying employer job postings and monitoring fake listings.
A21: Innovation Canvas | B21: Key Activities(name) | C21: AI Job Matching | D21: Implementing and refining AI algorithms for better job recommendations.
A22: Innovation Canvas | B22: Key Activities(name) | C22: Marketing & Outreach | D22: Digital marketing campaigns to attract job seekers and employers.
A23: Innovation Canvas | B23: Key Resources(name) | C23: Software Developers | D23: 80,000 OMR annually
A24: Innovation Canvas | B24: Key Resources(name) | C24: AI Algorithms | D24: 25,000 OMR research & development
A25: Innovation Canvas | B25: Key Resources(name) | C25: Marketing & Branding | D25: 40,000 OMR per year
A26: Innovation Canvas | B26: Key Resources(name) | C26: Customer Support Team | D26: 30,000 OMR annually
A27: Innovation Canvas | B27: Key Partnerships(name) | C27: Universities & Training Centers | D27: Collaboration to help fresh graduates find jobs and improve skills.
A28: Innovation Canvas | B28: Key Partnerships(name) | C28: Corporate Employers | D28: Partnerships to list verified job openings and internships.
A29: Innovation Canvas | B29: Key Partnerships(name) | C29: Government Agencies | D29: Working with labor and employment ministries for regulatory compliance.
A30: Innovation Canvas | B30: Key Partnerships(name) | C30: Recruitment Agencies | D30: Integrating their job postings and hiring services into the platform.

Sheet customer
A1: section | B1: field | C1: value1 | D1: value2
A2: Innovation Canvas | B2: segments | C2: =original!D2 -> Job Seekers (Fresh Graduates) | D2: =original!E2 -> 3 Million OMR
A3: Innovation Canvas | B3: Customer Segments(name) | C3: =original!D3 -> Skilled Professionals | D3: =original!E3 -> 4 Million OMR
A4: Innovation Canvas | B4: Customer Segments(name) | C4: =original!D4 -> Employers & Companies (SMEs, Corporates) | D4: =original!E4 -> 6 Million OMR
A5: Innovation Canvas | B5: Customer Segments(name) | C5: =original!D5 -> Recruitment Agencies | D5: =original!E5 -> 2 Million OMR
A6: Innovation Canvas | B6: Customer Segments(name) | C6: =original!D6 -> Other Segments | D6: =original!E6 -> 2 Million OMR

Sheet value propositions
A1: section | B1: field | C1: value1 | D1: value2
A2: Innovation Canvas | B2: Value Propositions(name) | C2: =original!D7 -> AI-Powered Job Matching | D2: =original!E7 -> Uses AI to match job seekers with relevant job postings based on skills and experience.
A3: Innovation Canvas | B3: Value Propositions(name) | C3: =original!D8 -> Verified Employer Listings | D3: =original!E8 -> Ensures job listings are authentic and from credible companies.
A4: Innovation Canvas | B4: Value Propositions(name) | C4: =original!D9 -> Career Development & Upskilling | D4: =original!E9 -> Provides online courses, resume-building tools, and interview coaching.
A5: Innovation Canvas | B5: Value Propositions(name) | C5: =original!D10 -> Seamless Hiring Process | D5: =original!E10 -> Employers can streamline recruitment with automated shortlisting and scheduling.

Sheet channels
A1: section | B1: field | C1: value1 | D1: value2
A2: Innovation Canvas | B2: Sales Channels(eg. Distributor, direct,none) | C2: =original!D11 -> Direct Sales | D2: =original!E11 -> Subscription-based plans for employers and recruiters.
A3: Innovation Canvas | B3: Sales Channels(eg. Distributor, direct,none) | C3: =original!D12 -> Online Platform | D3: =original!E12 -> Web and mobile app for job seekers and recruiters.
A4: Innovation Canvas | B4: Sales Channels(eg. Distributor, direct,none) | C4: =original!D13 -> Partnerships | D4: =original!E13 -> Collaboration with universities, training centers, and businesses
A5: Innovation Canvas | B5: Sales Channels(eg. Distributor, direct,none) | C5: =original!D14 -> Other Channels | D5: =original!E14 -> 0

Sheet relationships
A1: section | B1: field | C1: value1 | D1: value2
A2: Innovation Canvas | B2: Customer Relationships | C2: =original!D15 -> 24/7 Live Chat Support | D2: =original!E15 -> Instant help for job seekers and employers.
A3: Innovation Canvas | B3: Customer Relationships | C3: =original!D16 -> WhatsApp & Email Support | D3: =original!E16 -> Easy access to customer support for queries.
A4: Innovation Canvas | B4: Customer Relationships | C4: =original!D17 -> Community Engagement | D4: =original!E17 -> Online forums, blogs, and networking events for career advice.
A5: Innovation Canvas | B5: Customer Relationships | C5: =original!D18 -> Other Customer Relationship | D5: =original!E18 -> 0

Sheet activities
A1: section | B1: field | C1: value1 | D1: value2
A2: Innovation Canvas | B2: Key Activities(name) | C2: =original!D19 -> Platform Development | D2: =original!E19 -> Building and maintaining the web & mobile application.
A3: Innovation Canvas | B3: Key Activities(name) | C3: =original!D20 -> Job Listings Management | D3: =original!E20 -> Verifying employer job postings and monitoring fake listings.
A4: Innovation Canvas | B4: Key Activities(name) | C4: =original!D21 -> AI Job Matching | D4: =original!E21 -> Implementing and refining AI algorithms for better job recommendations.
A5: Innovation Canvas | B5: Key Activities(name) | C5: =original!D22 -> Marketing & Outreach | D5: =original!E22 -> Digital marketing campaigns to attract job seekers and employers.

Sheet resources
A1: section | B1: field | C1: value1 | D1: value2
A2: Innovation Canvas | B2: Key Resources(name) | C2: =original!D23 -> Software Developers | D2: =original!E23 -> 80,000 OMR annually
A3: Innovation Canvas | B3: Key Resources(name) | C3: =original!D24 -> AI Algorithms | D3: =original!E24 -> 25,000 OMR research & development
A4: Innovation Canvas | B4: Key Resources(name) | C4: =original!D25 -> Marketing & Branding | D4: =original!E25 -> 40,000 OMR per year
A5: Innovation Canvas | B5: Key Resources(name) | C5: =original!D26 -> Customer Support Team | D5: =original!E26 -> 30,000 OMR annually

Sheet partnerships
A1: section | B1: field | C1: value1 | D1: value2
A2: Innovation Canvas | B2: Key Partnerships(name) | C2: =original!D27 -> Universities & Training Centers | D2: =original!E27 -> Collaboration to help fresh graduates find jobs and improve skills.
A3: Innovation Canvas | B3: Key Partnerships(name) | C3: =original!D28 -> Corporate Employers | D3: =original!E28 -> Partnerships to list verified job openings and internships.
A4: Innovation Canvas | B4: Key Partnerships(name) | C4: =original!D29 -> Government Agencies | D4: =original!E29 -> Working with labor and employment ministries for regulatory compliance.
A5: Innovation Canvas | B5: Key Partnerships(name) | C5: =original!D30 -> Recruitment Agencies | D5: =original!E30 -> Integrating their job postings and hiring services into the platform.

Sheet revenue_streams
A1: section | B1: field | C1: value
A2: Innovation Canvas | B2: =original!D32 -> Royalty | C2: =original!E32 -> 1000
A3: Innovation Canvas | B3: =original!D33 -> Fees | C3: =original!E33 -> 1000
A4: Innovation Canvas | B4: =original!D34 -> spinoff | C4: =original!E34 -> 1000
A5: Innovation Canvas | B5: =original!D35 -> Franchise | C5: =original!E35 -> 1000
A6: Innovation Canvas | B6: =original!D36 -> Other | C6: =original!E36 -> 1000
A7: Innovation Canvas | B7: =original!D37 -> Total | C7: =original!E37 -> 5000

Sheet cost_structure
A1: section | B1: field | C1: value
A2: Innovation Canvas | B2: =original!D38 -> COGS/Cost of Sales for Royalty | C2: =original!E38 -> 400
A3: Innovation Canvas | B3: =original!D39 -> COGS/Cost of Sales for Fees | C3: =original!E39 -> 400
A4: Innovation Canvas | B4: =original!D40 -> COGS/Cost of Sales for spinoff | C4: =original!E40 -> 400
A5: Innovation Canvas | B5: =original!D41 -> COGS/Cost of Sales for Franchise | C5: =original!E41 -> 400
A6: Innovation Canvas | B6: =original!D42 -> COGS/Cost of Sales for Other | C6: =original!E42 -> 400
A7: Innovation Canvas | B7: =original!D43 -> Total COGS/Cost of Sales | C7: =original!E43 -> 2000
A8: Innovation Canvas | B8: =original!D44 -> Operating costs | C8: =original!E44 -> 500
A9: Innovation Canvas | B9: =original!D45 -> Direct Fixed costs(Assets+Development cost) | C9: =original!E45 -> 5000
A10: Innovation Canvas | B10: =original!D46 -> Other Cost(Name of Cost) | C10: =original!E46 -> 1000
A11: Innovation Canvas | B11: =original!D47 -> Total Costs | C11: =original!E47 -> 8500

Sheet commercialization_matrix
A1: section | B1: field | C1: factor | D1: royalty_scale | E1: royalty_charges | F1: fees_scale | G1: fees_charges | H1: spinoff_scale | I1: spinoff_charges | J1: franchise_scale | K1: franchise_charges | L1: others_scale | M1: others_charges
A2: Innovation Canvas | B2: =original!D51 -> Strength of idea/ Concept | C2: =original!E51 -> 1 | D2: =original!F51 -> 5 | E2: =original!G51 -> 5 | F2: =original!H51 -> 0 | G2: =original!I51 -> 0 | H2: =original!J51 -> 0 | I2: =original!K51 -> 0 | ... M2: =original!O51 -> 5
A3: Innovation Canvas | B3: =original!D52 -> Prototype readiness for commercialisation | C3: =original!E52 -> 2 | D3: =original!F52 -> 4 | E3: =original!G52 -> 8 | F3: =original!H52 -> 0 | G3: =original!I52 -> 0 | H3: =original!J52 -> 0 | I3: =original!K52 -> 0 | ... M3: =original!O52 -> 8
A4: Innovation Canvas | B4: =original!D53 -> Completion & Quality of Piloting Scale | C4: =original!E53 -> 3 | D4: =original!F53 -> 3 | E4: =original!G53 -> 9 | F4: =original!H53 -> 0 | G4: =original!I53 -> 0 | H4: =original!J53 -> 0 | I4: =original!K53 -> 0 | ... M4: =original!O53 -> 9
A5: Innovation Canvas | B5: =original!D54 -> IP Protection Strength | C5: =original!E54 -> 5 | D5: =original!F54 -> 5 | E5: =original!G54 -> 25 | F5: =original!H54 -> 0 | G5: =original!I54 -> 0 | H5: =original!J54 -> 0 | I5: =original!K54 -> 0 | ... M5: =original!O54 -> 25
A6: Innovation Canvas | B6: =original!D55 -> Branding Readiness | C6: =original!E55 -> 5 | D6: =original!F55 -> 2 | E6: =original!G55 -> 10 | F6: =original!H55 -> 0 | G6: =original!I55 -> 0 | H6: =original!J55 -> 0 | I6: =original!K55 -> 0 | ... M6: =original!O55 -> 10
A7: Innovation Canvas | B7: =original!D56 -> Commercialisation Readiness | C7: =original!E56 -> 10 | D7: =original!F56 -> 5 | E7: =original!G56 -> 50 | F7: =original!H56 -> 0 | G7: =original!I56 -> 0 | H7: =original!J56 -> 0 | I7: =original!K56 -> 0 | ... M7: =original!O56 -> 50
A8: Innovation Canvas | B8: =original!D57 -> Exclusivity (0 score no Execlusivity & 5 Full Execlusivity) | C8: =original!E57 -> 100 | D8: =original!F57 -> 0 | E8: =original!G57 -> 0 | F8: =original!H57 -> 0 | G8: =original!I57 -> 0 | H8: =original!J57 -> 0 | I8: =original!K57 -> 0 | ... M8: =original!O57 -> 0
A9: Innovation Canvas | B9: =original!D58 -> Total score = | C9: =original!E58 -> 0 | D9: =original!F58 -> 24 | E9: =original!G58 -> 0 | F9: =original!H58 -> 0 | G9: =original!I58 -> 0 | H9: =original!J58 -> 0 | I9: =original!K58 -> 0 | ... M9: =original!O58 -> 0
A10: Innovation Canvas | B10: =original!D59 -> Total Charges = | C10: =original!E59 -> 0 | D10: =original!F59 -> 0 | E10: =original!G59 -> 107 | F10: =original!H59 -> 0 | G10: =original!I59 -> 0 | H10: =original!J59 -> 0 | I10: =original!K59 -> 0 | ... M10: =original!O59 -> 107

Sheet overall_feasibility_analysis
A1: section | B1: field | C1: revenue | D1: cogs | E1: gross_profit | F1: gross_profit_percentage
A2: Overall Feasibility Analysis | B2: =original!D61 -> Royalty | C2: =original!E61 -> 1000 | D2: =original!F61 -> 400 | E2: =original!G61 -> 600 | F2: =original!H61 -> 0.6
A3: Overall Feasibility Analysis | B3: =original!D62 -> Fees | C3: =original!E62 -> 1000 | D3: =original!F62 -> 400 | E3: =original!G62 -> 600 | F3: =original!H62 -> 0.6
A4: Overall Feasibility Analysis | B4: =original!D63 -> spinoff | C4: =original!E63 -> 1000 | D4: =original!F63 -> 400 | E4: =original!G63 -> 600 | F4: =original!H63 -> 0.6
A5: Overall Feasibility Analysis | B5: =original!D64 -> Franchise | C5: =original!E64 -> 1000 | D5: =original!F64 -> 400 | E5: =original!G64 -> 600 | F5: =original!H64 -> 0.6
A6: Overall Feasibility Analysis | B6: =original!D65 -> Other | C6: =original!E65 -> 1000 | D6: =original!F65 -> 400 | E6: =original!G65 -> 600 | F6: =original!H65 -> 0.6
A7: Overall Feasibility Analysis | B7: =original!D66 -> Total | C7: =original!E66 -> 5000 | D7: =original!F66 -> 2000 | E7: =original!G66 -> 3000 | F7: =original!H66 -> 0.6

Sheet overall_feasibility_analysi (2)
B1: Overall Feasibility Analysis | C1: =original!D67 -> Total Annual Revenue( from revenue streams value from canvas) | D1: =original!E67 -> 5000
B2: Overall Feasibility Analysis | C2: =original!D68 -> COGS/Cost of Sales(from cogs/costs of sales value from canvas) | D2: =original!E68 -> 2000
B3: Overall Feasibility Analysis | C3: =original!D69 -> Gross Profit(value in OMR) | D3: =original!E69 -> 3000
B4: Overall Feasibility Analysis | C4: =original!D70 -> Gross Profit (in %) | D4: =original!E70 -> 0.6
B5: Overall Feasibility Analysis | C5: =original!D71 -> Operating Costs(from total costs value from canvas) | D5: =original!E71 -> 500
B6: Overall Feasibility Analysis | C6: =original!D72 -> Net Profit(value in OMR) | D6: =original!E72 -> 2500
B7: Overall Feasibility Analysis | C7: =original!D73 -> Gross Profit (in %) | D7: =original!E73 -> 0.5
B8: Overall Feasibility Analysis | C8: =original!D74 -> Direct Fixed+ Other costs | D8: =original!E74 -> 6000
B9: Overall Feasibility Analysis | C9: =original!D75 -> Return on Investment =(net profit-investment)/investment*100 | D9: =original!E75 -> 0.41666667
B10: Overall Feasibility Analysis | C10: =original!D76 -> Pay-Back period (in years) | D10: =original!E76 -> 2.4

Sheet Sheet2 (2)
C1: Charges/unit | D1: Scale | M1: Score | Q1: Charges
B2: Commercialisation charges/ Royality Feasibility matrix | D2: 0 | E2: 1 | F2: 2 | G2: 3 | H2: 4 | I2: 5 | J2: Score | K2: Charges | M2: SI-6 | N2: Eco House | O2: Green House | Q2: SI-6 | R2: Eco House | S2: Green House
B3: Strength of idea/ Concept: O- 5 × 5 OMR | C3: 5 | I3: =I2*C3 -> 25 | J3: =K3/C3 -> 5 | K3: =SUM(D3:I3) -> 25 | M3: 5 | N3: 5 | O3: 1 | Q3: =C3*M3 -> 25 | R3: =C3*N3 -> 25 | S3: =C3*O3 -> 5
B4: Prototype readiness for commercialisation: 0-5×10 OMR | C4: 10 | F4: =C4*F2 -> 20 | J4: =K4/C4 -> 2 | K4: =SUM(D4:I4) -> 20 | M4: 4 | N4: 4 | O4: 4 | Q4: =C4*M4 -> 40 | R4: =C4*N4 -> 40 | S4: =C4*O4 -> 40
B5: Piloting Scale :0-5 × 100 | C5: 100 | G5: =C5*G2 -> 300 | J5: =K5/C5 -> 3 | K5: =SUM(D5:I5) -> 300 | M5: 4 | N5: 4 | O5: 4 | Q5: =C5*M5 -> 400 | R5: =C5*N5 -> 400 | S5: =C5*O5 -> 400
B6: Franchising Fees: 0-5× 100 | C6: 100 | H6: =C6*H2 -> 400 | J6: =K6/C6 -> 4 | K6: =SUM(D6:I6) -> 400 | M6: 0 | N6: 0 | O6: 0 | Q6: =C6*M6 -> 0 | R6: =C6*N6 -> 0 | S6: =C6*O6 -> 0
B7: IP Strength : 0 × 5 × 100 OMR | C7: 100 | I7: =C7*I2 -> 500 | J7: =K7/C7 -> 5 | K7: =SUM(D7:I7) -> 500 | M7: 4 | N7: 4 | O7: 2 | Q7: =C7*M7 -> 400 | R7: =C7*N7 -> 400 | S7: =C7*O7 -> 200
B8: Branding readiness :0-5 × 100 OMR | C8: 100 | F8: =C8*F2 -> 200 | J8: =K8/C8 -> 2 | K8: =SUM(D8:I8) -> 200 | M8: 4 | N8: 5 | O8: 2 | Q8: =C8*M8 -> 400 | R8: =C8*N8 -> 500 | S8: =C8*O8 -> 200
B9: commercialisation Readiness: 0-5×100 OMR | C9: 100 | G9: =C9*G2 -> 300 | J9: =K9/C9 -> 3 | K9: =SUM(D9:I9) -> 300 | M9: 4 | N9: 5 | O9: 2 | Q9: =C9*M9 -> 400 | R9: =C9*N9 -> 500 | S9: =C9*O9 -> 200
B10: Exclusivity: :0-5×100 OMR | C10: 1000 | H10: =C10*H2 -> 4000 | J10: =K10/C10 -> 4 | K10: =SUM(D10:I10) -> 4000 | M10: 0 | N10: 0 | Q10: =C10*M10 -> 0 | R10: =IF(N10=0,0,C10*(5-N10+1)) -> 0 | S10: =C10*O10 -> 0
B11: Total score = | J11: =SUM(J3:J10) -> 28 | M11: =SUM(M3:M10) -> 25 | N11: =SUM(N3:N10) -> 27 | O11: =SUM(O3:O10) -> 15 | Q11: =SUM(Q3:Q10) -> 1665 | R11: =SUM(R3:R10) -> 1865 | S11: =SUM(S3:S10) -> 1045
B12: Total Charges = | K12: =SUM(K3:K10) -> 5745
M13: =COUNT(C3:C10)*5 -> 40
B14: Total Fix Cahrge | Q14: =M11*4 -> 100 | R14: =N11*4 -> 108 | S14: =O11*4 -> 60
B15: Franchising Fees: 0-5× 100 | C15: 100 | H15: =C15*H11 -> 0 | J15: =K15/C15 -> 0 | K15: =SUM(D15:I15) -> 0 | M15: 0 | N15: 5 | O15: 5 | Q15: =C15*M15 -> 0 | R15: =C15*N15 -> 500 | S15: =C15*O15 -> 500
B16: Total Charges
E17: Innovation canvas --> innovation fininacial plan simulation-->commercialization feasibility
B19: Exclusivity
Q20: Number of targeted clients | R20: Revenue
B21: 1- Maximum exclusivity | N21: Customer by regions | O21: Oman | Q21: 10 | R21: =Q21*$Q$14 -> 1000
B22: 5- Maximum 5 clients | O22: Iran | Q22: 1000 | R22: =Q22*$Q$14 -> 100000
B23: 0 | C23: None | O23: Malaysia | Q23: 1000 | R23: =Q23*$Q$14 -> 100000
B24: 1 | C24: 1 person | Q24: =SUM(Q21:Q23) -> 2010 | R24: =SUM(R21:R23) -> 201000
B25: 2 | C25: =B25&" person" -> 2 person
B26: 3 | C26: =B26&" person" -> 3 person | H26: Customer Segments(name) | Q26: Number of targeted clients | R26: Revenue
B27: 4 | C27: =B27&" person" -> 4 person | H27: Value Propositions(name) | N27: Customer Segments | O27: Oman | Q27: 10 | R27: =Q27*$Q$14 -> 1000
B28: 5 | C28: =B28&" person" -> 5 person | H28: Sales Channels(eg. Distributor, direct,none) | O28: Iran | Q28: 1000 | R28: =Q28*$Q$14 -> 100000
H29: Customer Relationships(example service call center/email/whatsapp) | O29: Malaysia | Q29: 1000 | R29: =Q29*$Q$14 -> 100000
H30: Key Activities(name) | Q30: =SUM(Q27:Q29) -> 2010 | R30: =SUM(R27:R29) -> 201000
H31: Key Resources(name)
H32: Key Partnerships(name)
K33: Region | L33: Segment | M33: Channel | N33: Partners
H34: Number of Customers | K34: Segments
H35: Region | I35: Channel | J35: Partners | K35: Royalty | L35: Fees | M35: spinoff | N35: Franchise | O35: Other | P35: Total
H36: Oman | I36: Segment 1 | J36: Partners1 | P36: =SUM(K36:O36) -> 0
J37: Partners2 | P37: =SUM(K37:O37) -> 0
J38: Partners3 | P38: =SUM(K38:O38) -> 0
I39: Segment 2 | J39: Partners4 | P39: =SUM(K39:O39) -> 0
J40: Partners5 | P40: =SUM(K40:O40) -> 0
J41: Partners6 | P41: =SUM(K41:O41) -> 0
...

Sheet Sheet4
J1: Number of targeted clients | K1: Revenue
G2: Customer by regions | H2: Oman | J2: 10 | K2: =J2*$Q$14 -> 0
H3: Iran | J3: 1000 | K3: =J3*$Q$14 -> 0
H4: Malaysia | J4: 1000 | K4: =J4*$Q$14 -> 0
J5: =SUM(J2:J4) -> 2010 | K5: =SUM(K2:K4) -> 0
A7: Customer Segments(name) | J7: Number of targeted clients | K7: Revenue
A8: Value Propositions(name) | G8: Customer Segments | H8: Oman | J8: 10 | K8: =J8*$Q$14 -> 0
A9: Sales Channels(eg. Distributor, direct,none) | H9: Iran | J9: 1000 | K9: =J9*$Q$14 -> 0
A10: Customer Relationships(example service call center/email/whatsapp) | H10: Malaysia | J10: 1000 | K10: =J10*$Q$14 -> 0
A11: Key Activities(name) | J11: =SUM(J8:J10) -> 2010 | K11: =SUM(K8:K10) -> 0
A12: Key Resources(name)
A13: Key Partnerships(name)
D14: Region | E14: Segment | F14: Channel | G14: Partners
D15: A
D16: B
G17: Segments
D18: Region | E18: Channel | F18: Partners | G18: Royalty | H18: Fees | I18: spinoff | J18: Franchise | K18: Other | L18: Total
D19: Oman | E19: Segment 1 | F19: Partners1 | L19: =SUM(G19:K19) -> 0
F20: Partners2 | L20: =SUM(G20:K20) -> 0
F21: Partners3 | L21: =SUM(G21:K21) -> 0
E22: Segment 2 | F22: Partners4 | L22: =SUM(G22:K22) -> 0
F23: Partners5 | L23: =SUM(G23:K23) -> 0
F24: Partners6 | L24: =SUM(G24:K24) -> 0
E25: Segment3 | F25: Partners7 | L25: =SUM(G25:K25) -> 0
F26: Partners8 | L26: =SUM(G26:K26) -> 0
F27: Partners9 | L27: =SUM(G27:K27) -> 0
D28: Total | G28: =SUM(G19:G27) -> 0 | H28: =SUM(H19:H27) -> 0 | I28: =SUM(I19:I27) -> 0 | J28: =SUM(J19:J27) -> 0 | K28: =SUM(K19:K27) -> 0 | L28: =SUM(L19:L27) -> 0
