Workbook

Sheet Commercialisation Model
B1: Commercialisation Model (Product Wise) eg, SI-6
D2: Score Calculations | J2: Business Channel (Select one from dropdown Menue), then Set Scores & Calculate Charges
B3: Commercialization Matrix | C3: Score Points | D3: Royalty | E3: Fees | F3: spinoff | G3: Franchise | H3: Other | I3: Factor | J3: Royalty | K3: Fees | L3: spinoff | M3: Franchise | N3: Other | O3: Total
B4: Strength of idea/ Concept | C4: 1 to 5*1 | D4: 5 | G4: 5 | I4: 1 | J4: =D4*$I4 -> 5 | K4: =E4*$I4 -> 0 | L4: =F4*$I4 -> 0 | M4: =G4*$I4 -> 5 | N4: =H4*$I4 -> 0 | O4: =SUM(J4:N4) -> 10
B5: Prototype readiness for commercialisation | C5: 1 to 5*2 | D5: 4 | G5: 4 | I5: 2 | J5: =D5*$I5 -> 8 | K5: =E5*$I5 -> 0 | L5: =F5*$I5 -> 0 | M5: =G5*$I5 -> 8 | N5: =H5*$I5 -> 0 | O5: =SUM(J5:N5) -> 16
B6: Completion & Quality of Piloting Scale | C6: 1 to 5*3 | D6: 3 | G6: 3 | I6: 3 | J6: =D6*$I6 -> 9 | K6: =E6*$I6 -> 0 | L6: =F6*$I6 -> 0 | M6: =G6*$I6 -> 9 | N6: =H6*$I6 -> 0 | O6: =SUM(J6:N6) -> 18
B7: IP Protection Strength | C7: 1 to 5*5 | D7: 5 | G7: 5 | I7: 5 | J7: =D7*$I7 -> 25 | K7: =E7*$I7 -> 0 | L7: =F7*$I7 -> 0 | M7: =G7*$I7 -> 25 | N7: =H7*$I7 -> 0 | O7: =SUM(J7:N7) -> 50
B8: Branding Readiness | C8: 1 to 5*5 | D8: 2 | G8: 2 | I8: 5 | J8: =D8*$I8 -> 10 | K8: =E8*$I8 -> 0 | L8: =F8*$I8 -> 0 | M8: =G8*$I8 -> 10 | N8: =H8*$I8 -> 0 | O8: =SUM(J8:N8) -> 20
B9: Commercialisation Readiness | C9: 1 to 5*10 | D9: 5 | G9: 5 | I9: 10 | J9: =D9*$I9 -> 50 | K9: =E9*$I9 -> 0 | L9: =F9*$I9 -> 0 | M9: =G9*$I9 -> 50 | N9: =H9*$I9 -> 0 | O9: =SUM(J9:N9) -> 100
B10: Exclusivity (0 score no Execlusivity & 5 Full Execlusivity) | C10: 1 to 5*100 | D10: 0 | G10: 5 | I10: 100 | J10: =D10*$I10 -> 0 | K10: =E10*$I10 -> 0 | L10: =F10*$I10 -> 0 | M10: =G10*$I10 -> 500 | N10: =H10*$I10 -> 0 | O10: =SUM(J10:N10) -> 500
B11: Total score = | D11: =SUM(D4:D10) -> 24 | E11: =SUM(E4:E10) -> 0 | F11: =SUM(F4:F10) -> 0 | G11: =SUM(G4:G10) -> 29 | H11: =SUM(H4:H10) -> 0
B12: Total Charges = | J12: =SUM(J4:J10) -> 107 | K12: =SUM(K4:K10) -> 0 | L12: =SUM(L4:L10) -> 0 | M12: =SUM(M4:M10) -> 607 | N12: =SUM(N4:N10) -> 0 | O12: =SUM(O4:O10) -> 714
B13: Packages | C13: Charges in OMR
B14: Bronze | C14: =_xlfn.FLOOR.MATH($J12/2,10) -> 50
B15: Silver | C15: =_xlfn.FLOOR.MATH($J12,10) -> 100
B16: Gold | C16: =_xlfn.FLOOR.MATH($J12,10)*5 -> 500
B18: Targeted Markets | E18: Targeted Number of Customers & Revenue
B19: Region | C19: Segments/Sectors | D19: Partners | E19: Bronze | F19: Silver | G19: Gold | H19: Other | I19: Other | J19: Total
B20: Oman (Projected Number of Customers) | C20: SI6/Garages | D20: Partners1 | E20: 100 | F20: 120 | G20: 100 | J20: =SUM(E20:I20) -> 320
D21: Partners2 | E21: 100 | F21: 120 | G21: 100 | J21: =SUM(E21:I21) -> 320
D22: Partners3 | E22: 100 | F22: 120 | G22: 100 | J22: =SUM(E22:I22) -> 320
C23: SI6/Services | D23: Partners4 | E23: 100 | F23: 120 | G23: 100 | J23: =SUM(E23:I23) -> 320
D24: Partners5 | E24: 100 | F24: 120 | G24: 100 | J24: =SUM(E24:I24) -> 320
D25: Partners6 | E25: 100 | F25: 120 | G25: 100 | J25: =SUM(E25:I25) -> 320
C26: SI6/Food & Beverages | D26: Partners7 | E26: 100 | F26: 120 | G26: 100 | J26: =SUM(E26:I26) -> 320
D27: Partners8 | E27: 100 | F27: 120 | G27: 100 | J27: =SUM(E27:I27) -> 320
D28: Partners9 | E28: 100 | F28: 120 | G28: 100 | J28: =SUM(E28:I28) -> 320
C29: Other(provision) | J29: =SUM(E29:I29) -> 0
J30: =SUM(E30:I30) -> 0
J31: =SUM(E31:I31) -> 0
C32: Other(provision) | J32: =SUM(E32:I32) -> 0
J33: =SUM(E33:I33) -> 0
J34: =SUM(E34:I34) -> 0
C35: Other(provision) | J35: =SUM(E35:I35) -> 0
J36: =SUM(E36:I36) -> 0
J37: =SUM(E37:I37) -> 0
C38: Other(provision) | J38: =SUM(E38:I38) -> 0
J39: =SUM(E39:I39) -> 0
J40: =SUM(E40:I40) -> 0
B41: Total Number of Customers -Oman | E41: =SUM(E20:E40) -> 900 | F41: =SUM(F20:F40) -> 1080 | G41: =SUM(G20:G40) -> 900 | H41: =SUM(H20:H40) -> 0 | I41: =SUM(I20:I40) -> 0 | J41: =SUM(E41:I41) -> 2880
...

Sheet investment_strength_matrix
A1: field | B1: royalty_price | C1: fees_price | D1: spinoff_price | E1: franchise_price | F1: other_price | G1: total_price
A2: Strength of idea/ Concept | B2: ='Commercialisation Model'!D4*'Commercialisation Model'!$I4 -> 5 | C2: ='Commercialisation Model'!E4*'Commercialisation Model'!$I4 -> 0 | D2: ='Commercialisation Model'!F4*'Commercialisation Model'!$I4 -> 0 | E2: ='Commercialisation Model'!G4*'Commercialisation Model'!$I4 -> 5 | F2: ='Commercialisation Model'!H4*'Commercialisation Model'!$I4 -> 0 | G2: =SUM(B2:F2) -> 10
A3: Prototype readiness for commercialisation | B3: ='Commercialisation Model'!D5*'Commercialisation Model'!$I5 -> 8 | C3: ='Commercialisation Model'!E5*'Commercialisation Model'!$I5 -> 0 | D3: ='Commercialisation Model'!F5*'Commercialisation Model'!$I5 -> 0 | E3: ='Commercialisation Model'!G5*'Commercialisation Model'!$I5 -> 8 | F3: ='Commercialisation Model'!H5*'Commercialisation Model'!$I5 -> 0 | G3: =SUM(B3:F3) -> 16
A4: Completion & Quality of Piloting Scale | B4: ='Commercialisation Model'!D6*'Commercialisation Model'!$I6 -> 9 | C4: ='Commercialisation Model'!E6*'Commercialisation Model'!$I6 -> 0 | D4: ='Commercialisation Model'!F6*'Commercialisation Model'!$I6 -> 0 | E4: ='Commercialisation Model'!G6*'Commercialisation Model'!$I6 -> 9 | F4: ='Commercialisation Model'!H6*'Commercialisation Model'!$I6 -> 0 | G4: =SUM(B4:F4) -> 18
A5: IP Protection Strength | B5: ='Commercialisation Model'!D7*'Commercialisation Model'!$I7 -> 25 | C5: ='Commercialisation Model'!E7*'Commercialisation Model'!$I7 -> 0 | D5: ='Commercialisation Model'!F7*'Commercialisation Model'!$I7 -> 0 | E5: ='Commercialisation Model'!G7*'Commercialisation Model'!$I7 -> 25 | F5: ='Commercialisation Model'!H7*'Commercialisation Model'!$I7 -> 0 | G5: =SUM(B5:F5) -> 50
A6: Branding Readiness | B6: ='Commercialisation Model'!D8*'Commercialisation Model'!$I8 -> 10 | C6: ='Commercialisation Model'!E8*'Commercialisation Model'!$I8 -> 0 | D6: ='Commercialisation Model'!F8*'Commercialisation Model'!$I8 -> 0 | E6: ='Commercialisation Model'!G8*'Commercialisation Model'!$I8 -> 10 | F6: ='Commercialisation Model'!H8*'Commercialisation Model'!$I8 -> 0 | G6: =SUM(B6:F6) -> 20
A7: Commercialisation Readiness | B7: ='Commercialisation Model'!D9*'Commercialisation Model'!$I9 -> 50 | C7: ='Commercialisation Model'!E9*'Commercialisation Model'!$I9 -> 0 | D7: ='Commercialisation Model'!F9*'Commercialisation Model'!$I9 -> 0 | E7: ='Commercialisation Model'!G9*'Commercialisation Model'!$I9 -> 50 | F7: ='Commercialisation Model'!H9*'Commercialisation Model'!$I9 -> 0 | G7: =SUM(B7:F7) -> 100
A8: Exclusivity (0 score no Execlusivity & 5 Full Execlusivity) | B8: ='Commercialisation Model'!D10*'Commercialisation Model'!$I10 -> 0 | C8: ='Commercialisation Model'!E10*'Commercialisation Model'!$I10 -> 0 | D8: ='Commercialisation Model'!F10*'Commercialisation Model'!$I10 -> 0 | E8: ='Commercialisation Model'!G10*'Commercialisation Model'!$I10 -> 500 | F8: ='Commercialisation Model'!H10*'Commercialisation Model'!$I10 -> 0 | G8: =SUM(B8:F8) -> 500
A9: Total score = | B9: =ROUNDDOWN(SUM(B2:B8),10) -> 107 | C9: =SUM(C2:C8) -> 0 | D9: =SUM(D2:D8) -> 0 | E9: =SUM(E2:E8) -> 607 | F9: =SUM(F2:F8) -> 0 | G9: =SUM(G2:G8) -> 714
A10: Total Charges = | B10: =B9 -> 107 | C10: =C9 -> 0 | D10: =D9 -> 0 | E10: =E9 -> 607 | F10: =F9 -> 0

Sheet packages
A1: field | B1: bronze | C1: silver | D1: gold
A2: Charges (in OMR) | B2: =_xlfn.FLOOR.MATH(investment_strength_matrix!$B10/2,10) -> 50 | C2: =_xlfn.FLOOR.MATH(investment_strength_matrix!$B10,10) -> 100 | D2: =_xlfn.FLOOR.MATH(investment_strength_matrix!$B10,10)*5 -> 500

Sheet customers_revenue
A1: field | B1: bronze | C1: silver | D1: gold | E1: other1 | F1: other2 | G1: total
A2: Total Number of Customers -Oman | B2: ='Commercialisation Model'!E41 -> 900 | C2: ='Commercialisation Model'!F41 -> 1080 | D2: ='Commercialisation Model'!G41 -> 900 | E2: ='Commercialisation Model'!H41 -> 0 | F2: ='Commercialisation Model'!I41 -> 0 | G2: ='Commercialisation Model'!J41 -> 2880
A3: Total Revenue ( in OMR)-Oman | B3: ='Commercialisation Model'!E42 -> 22500 | C3: ='Commercialisation Model'!F42 -> 108000 | D3: ='Commercialisation Model'!G42 -> 450000 | E3: ='Commercialisation Model'!H42 -> 0 | F3: ='Commercialisation Model'!I42 -> 0 | G3: ='Commercialisation Model'!J42 -> 580500
A4: Total Number of Customers -Iran | B4: ='Commercialisation Model'!E64 -> 900 | C4: ='Commercialisation Model'!F64 -> 1080 | D4: ='Commercialisation Model'!G64 -> 900 | E4: ='Commercialisation Model'!H64 -> 0 | F4: ='Commercialisation Model'!I64 -> 0 | G4: =SUM(B4:F4) -> 2880
A5: Total Revenue ( in OMR)-Iran | B5: ='Commercialisation Model'!E65 -> 22500 | C5: ='Commercialisation Model'!F65 -> 108000 | D5: ='Commercialisation Model'!G65 -> 450000 | E5: ='Commercialisation Model'!H65 -> 0 | F5: ='Commercialisation Model'!I65 -> 0 | G5: =SUM(B5:F5) -> 580500
A6: Total Number of Customers -Malaysia | B6: ='Commercialisation Model'!E87 -> 900 | C6: ='Commercialisation Model'!F87 -> 1080 | D6: ='Commercialisation Model'!G87 -> 900 | E6: ='Commercialisation Model'!H87 -> 0 | F6: ='Commercialisation Model'!I87 -> 0 | G6: =SUM(B6:F6) -> 2880
A7: Total Revenue ( in OMR)-Malaysia | B7: ='Commercialisation Model'!E88 -> 22500 | C7: ='Commercialisation Model'!F88 -> 108000 | D7: ='Commercialisation Model'!G88 -> 450000 | E7: ='Commercialisation Model'!H88 -> 0 | F7: ='Commercialisation Model'!I88 -> 0 | G7: =SUM(B7:F7) -> 580500
A8: Total Number of Customers | B8: =B2+B4+B6 -> 2700 | C8: =C2+C4+C6 -> 3240 | D8: =D2+D4+D6 -> 2700 | E8: =E2+E4+E6 -> 0 | F8: =F2+F4+F6 -> 0 | G8: =G2+G4+G6 -> 8640
A9: Total Revenues ( in OMR) | B9: =B3+B5+B7 -> 67500 | C9: =C3+C5+C7 -> 324000 | D9: =D3+D5+D7 -> 1350000 | E9: =E3+E5+E7 -> 0 | F9: =F3+F5+F7 -> 0 | G9: =G3+G5+G7 -> 1741500
